Workbook
Name a: #REF!
Name agosto: #REF!
Name ano: #REF!
Name ANUAL: #REF!
Name ANUALL: #REF!
Name asd: #REF!
Name asdd: #REF!
Name asdf: #REF!
Name bdi: #REF!
Name bdis: #REF!
Name bg: #REF!
Name BN: #REF!
Name CASAMADEIRA: #REF!
Name cash_terminal: #REF!
Name ÇÇÇ: #REF!
Name cccccc: #REF!
Name cddddd: #REF!
Name COFINS: #REF!
Name dc: #REF!
Name dcf_year: #REF!
Name dd: #REF!
Name debt_terminal: #REF!
Name DespPPubFProm: '[1]desp op prom_obras'!#REF!
Name ds: #REF!
Name e: #REF!
Name EBITDA_mult: #REF!
Name ECECR: #REF!
Name er: #REF!
Name FF: #REF!
Name FWQFWFWQFWE: #REF!
Name GFNLHKNF: #REF!
Name GUCIGKJGJKFHTDMHGTDJY: #REF!
Name indicesss: #REF!
Name informe: #REF!
Name ITBI: '[2]desp op prom_obras'!#REF!
Name jfjfjfjfj: #REF!
Name jgjgj: #REF!
Name JORGE: #REF!
Name kasl: '[2]desp op prom_obras'!#REF!
Name kdkdkd: #REF!
Name Maf: #REF!
Name MatrizOcupAdim: #REF!
Name MENSAL: #REF!
Name Mensal.: #REF!
Name MOBILIA: #REF!
Name mult_sen: #REF!
Name n: #REF!
Name ng: #REF!
Name nhhhh: #REF!
Name NJDGFUDGE: #REF!
Name novva: #REF!
Name parcelamentorfb: #REF!
Name periodo_selecionado: #REF!
Name PeriodoInPlanejado: #REF!=MEDIAN(#REF!,#REF!,#REF!+#REF!-1)
Name PeriodoInReal: #REF!=MEDIAN(#REF!,#REF!,#REF!+#REF!-1)
Name Plano: 'DRE - Grafico'!PeriodoInPlanejado*(#REF!>0)
Name POOL: #REF!
Name POOLL: #REF!
Name PorcentagemConcluída: 'DRE - Grafico'!PorcentagemConcluídaPosterior*'DRE - Grafico'!PeriodoInPlanejado
Name PorcentagemConcluídaPosterior: (#REF!=MEDIAN(#REF!,#REF!,#REF!+#REF!)*(#REF!>0))*((#REF!<(INT(#REF!+#REF!*#REF!)))+(#REF!=#REF!))*(#REF!>0)

Sheet Fluxo Consolidado
L1: 2009558.1 | BB1: =AX3+BB3 -> 36144253 | BD1: =IRR(BD59:BD179,1%) -> 0.017079045 | BE1: =(1+BD1)^12-1 -> 0.22533963
A2: CRONOGRAMA | D2: RECEITA | P2: OBRA | X2: COMERCIALIZAÇÃO | AH2: DESPESAS ADMINISTRATIVAS | AP2: MÚTUO | AS2: RESUMO SEM ALAVANCAGEM | AX2: FLUXO CRI | BF2: RESUMO COM ALAVANCAGEM
A3: % | D3: =SUM(D59:D186) -> 1.0904974e+08 | E3: =SUM(E59:E186) -> 1.7149039e+08 | F3: =SUM(F59:F186) -> 1382206.7 | G3: 0.1 | H3: =SUM(H59:H186) -> -11265591 | I3: =SUM(I59:I186) -> 11265591 | J3: 0.005 | L3: =SUM(L5:L185) -> 3.6941881e+08 | M3: =SUM(M5:M185) -> 1000000 | N3: =SUM(N5:N185) -> 1493512 | O3: =SUM(O5:O185) -> 3539928.6 | P3: =SUM(P59:P186) -> -34953227 | Q3: =SUM(Q59:Q186) -> -3805740.3 | R3: =SUM(R59:R186) -> -13729000 | S3: =SUM(S59:S186) -> -600000 | T3: =SUM(T59:T186) -> -600000 | U3: =SUM(U59:U186) -> -375081.79 | V3: =SUM(V59:V186) -> -817651.46 | W3: =SUM(W59:W186) -> -2548350.2 | ... AO3: =SUM(AO59:AO186) -> -40000 | AP3: =SUM(AP58:AP186) -> -1248000 | AQ3: =SUM(AQ58:AQ186) -> -870000 | AS3: =SUM(AS5:AS186) -> 3.7545225e+08 | AT3: =SUM(AT5:AT186) -> -1.6981533e+08 | AU3: =SUM(AU5:AU186) -> 2.0563692e+08 | AV3: =AV186 -> 2.0563692e+08 | AX3: =SUM(AX58:AX238) -> 42000000 | AY3: =SUM(AY58:AY238) -> -27676170 | AZ3: =SUM(AZ58:AZ238) -> -48558231 | BA3: =SUM(BA58:BA238) -> -5183823.9 | BB3: =SUM(BB58:BB238) -> -5855747.1 | BC3: =SUM(BC58:BC238) -> 0 | BD3: =SUM(BD58:BD238) -> -45273972 | BE3: =SUM(BE58:BE238) -> -87273972 | BF3: =SUM(BF5:BF238) -> 3.3017828e+08 | BG3: =SUM(BG5:BG238) -> -1.6981533e+08 | BH3: =SUM(BH5:BH238) -> 1.6036295e+08 | BI3: =BI180 -> 1.6036295e+08
A4: N° | B4: EVENTO | C4: MESES | D4: ESTOQUE | E4: AGING DA CARTERIA | F4: RECUPERAÇÃO INADIMPLÊNCIA AGING | G4: INADIMPLÊNCIA | I4: RECUPERAÇÃO | J4: CORREÇÃO 0,5% | L4: RECEITA TOTAL | M4: EMPRESTIMO PF | N4: EMP. MUTUO ENTRE EMPRESAS | O4: OUTRAS ENTRADAS | P4: CRONOGRAMA OBRA | Q4: TAXA DE ADMINISTRAÇÃO | R4: FF&E | S4: INFRAESTRUTURA | T4: PARQUE AQ. | U4: PROJETO | V4: LEGALIZAÇÃO OBRA | W4: GERENCIAMENTO OBRA | X4: VENDAS GERAL | Y4: COMISSÃO PREVISTO | Z4: COMISSÃO FIXO | AA4: COMISSÃO REALIZADO/ PREMIAÇÃO | AB4: CLUB CIA PREVISTO | AC4: CLUB CIA REALIZADO | AD4: FÉRIAS CLUB | AE4: PASSAPORTE REALIZADO | AF4: PASSAPORTE PREVISTO | AG4: MARKETING, PROMOÇÃO E PROPAGANDA | AH4: GESTÃO DA CARTEIRA | AI4: HONORÁRIOS ADV | AJ4: HONORÁRIOS CONTABEIS / AUDITORIA | AK4: CORRESPONDÊNCIA E MALOTE | AL4: DISTRATO DE VENDA | AM4: DESPESAS BANCÁRIAS | AN4: IMPOSTOS (RET) | AO4: IPTU | AP4: EMPRESTIMO PF | AQ4: EMP. MUTUO ENTRE EMPRESAS | AS4: TOTAL RECEITA | AT4: TOTAL DESPESAS | AU4: SALDO MENSAL | AV4: SALDO ACUMULADO | AX4: LIBERAÇÃO | AY4: 1º PMT (AMORTIZAÇÃO + JUROS) | AZ4: 2º PMT (AMORTIZAÇÃO + JUROS) | BA4: DESPESAS RECORRENTES / DESPESAS GESTÃO | BB4: CUSTOS FLAT - ESTRUTURAÇÃO | BC4: FUNDO DE LIQUIDEZ | BD4: FLUXO MENSAL ECONOMICO | BE4: FLUXO MENSAL FINANCEIRO | BF4: TOTAL RECEITA | BG4: TOTAL DESPESAS | BH4: SALDO MENSAL | BI4: FLUXO ACUMULADO
C5: 41671 | L5: 0 | M5: 0 | N5: 0 | O5: 1000 | AS5: 1000 | AT5: =-3900000+3900000 -> 0 | AU5: =SUM(AS5:AT5) -> 1000 | AV5: =AU5 -> 1000 | BF5: =AS5 -> 1000 | BG5: =AT5 -> 0 | BH5: =AU5 -> 1000 | BI5: =AV5 -> 1000
C6: 41699 | L6: 0 | M6: 0 | N6: 0 | O6: 0 | AS6: 0 | AT6: 0 | AU6: =SUM(AS6:AT6) -> 0 | AV6: =AU6+AV5 -> 1000 | BF6: =AS6 -> 0 | BG6: =AT6 -> 0 | BH6: =AU6 -> 0 | BI6: =AV6 -> 1000
C7: 41730 | L7: 0 | M7: 0 | N7: 0 | O7: 9245.14 | AS7: 9245.14 | AT7: =-1559245.14+1550000 -> -9245.14 | AU7: =SUM(AS7:AT7) -> 1.0186341e-10 | AV7: =AU7+AV6 -> 1000 | BF7: =AS7 -> 9245.14 | BG7: =AT7 -> -9245.14 | BH7: =AU7 -> 1.0186341e-10 | BI7: =AV7 -> 1000
C8: 41760 | L8: 0 | M8: 0 | N8: 46553.47 | O8: 146407.45 | AS8: 192960.92 | AT8: -188312.22 | AU8: =SUM(AS8:AT8) -> 4648.7 | AV8: =AU8+AV7 -> 5648.7 | BF8: =AS8 -> 192960.92 | BG8: =AT8 -> -188312.22 | BH8: =AU8 -> 4648.7 | BI8: =AV8 -> 5648.7
C9: 41791 | L9: 0 | M9: 0 | N9: 3142.34 | O9: 56935.17 | AS9: 60077.51 | AT9: =-1630629.61+1576198.54 -> -54431.07 | AU9: =SUM(AS9:AT9) -> 5646.44 | AV9: =AU9+AV8 -> 11295.14 | BF9: =AS9 -> 60077.51 | BG9: =AT9 -> -54431.07 | BH9: =AU9 -> 5646.44 | BI9: =AV9 -> 11295.14
C10: 41821 | L10: 0 | M10: 0 | N10: 3568.76 | O10: 235374.71 | AS10: 238943.47 | AT10: -205847.51 | AU10: =SUM(AS10:AT10) -> 33095.96 | AV10: =AU10+AV9 -> 44391.1 | BF10: =AS10 -> 238943.47 | BG10: =AT10 -> -205847.51 | BH10: =AU10 -> 33095.96 | BI10: =AV10 -> 44391.1
C11: 41852 | L11: 0 | M11: 0 | N11: 0 | O11: 281736.14 | AS11: 281736.14 | AT11: -320861.45 | AU11: =SUM(AS11:AT11) -> -39125.31 | AV11: =AU11+AV10 -> 5265.79 | BF11: =AS11 -> 281736.14 | BG11: =AT11 -> -320861.45 | BH11: =AU11 -> -39125.31 | BI11: =AV11 -> 5265.79
C12: 41883 | L12: 0 | M12: 0 | N12: 0 | O12: 294606.73 | AS12: 294606.73 | AT12: -253992.76 | AU12: =SUM(AS12:AT12) -> 40613.97 | AV12: =AU12+AV11 -> 45879.76 | BF12: =AS12 -> 294606.73 | BG12: =AT12 -> -253992.76 | BH12: =AU12 -> 40613.97 | BI12: =AV12 -> 45879.76
C13: 41913 | L13: 0 | M13: 0 | N13: 41112.59 | O13: 336906.22 | AS13: 378018.81 | AT13: -367160.57 | AU13: =SUM(AS13:AT13) -> 10858.24 | AV13: =AU13+AV12 -> 56738 | BF13: =AS13 -> 378018.81 | BG13: =AT13 -> -367160.57 | BH13: =AU13 -> 10858.24 | BI13: =AV13 -> 56738
C14: 41944 | L14: 0 | M14: 0 | N14: 0 | O14: 334185.6 | AS14: 334185.6 | AT14: -361508.56 | AU14: =SUM(AS14:AT14) -> -27322.96 | AV14: =AU14+AV13 -> 29415.04 | BF14: =AS14 -> 334185.6 | BG14: =AT14 -> -361508.56 | BH14: =AU14 -> -27322.96 | BI14: =AV14 -> 29415.04
C15: 41974 | L15: 0 | M15: 0 | N15: 30000 | O15: 143859.64 | AS15: 173859.64 | AT15: -134974.89 | AU15: =SUM(AS15:AT15) -> 38884.75 | AV15: =AU15+AV14 -> 68299.79 | BF15: =AS15 -> 173859.64 | BG15: =AT15 -> -134974.89 | BH15: =AU15 -> 38884.75 | BI15: =AV15 -> 68299.79
C16: 42005 | L16: 22800.1 | M16: 0 | N16: 0 | O16: 106536.84 | AS16: 129336.94 | AT16: -126187.82 | AU16: =SUM(AS16:AT16) -> 3149.12 | AV16: =AU16+AV15 -> 71448.91 | BF16: =AS16 -> 129336.94 | BG16: =AT16 -> -126187.82 | BH16: =AU16 -> 3149.12 | BI16: =AV16 -> 71448.91
C17: 42036 | L17: 68481.75 | M17: 0 | N17: 40000 | O17: 171915.91 | AS17: 280397.66 | AT17: -315649.39 | AU17: =SUM(AS17:AT17) -> -35251.73 | AV17: =AU17+AV16 -> 36197.18 | BF17: =AS17 -> 280397.66 | BG17: =AT17 -> -315649.39 | BH17: =AU17 -> -35251.73 | BI17: =AV17 -> 36197.18
C18: 42064 | L18: 188382.86 | M18: 0 | N18: 0 | O18: 361130.16 | AS18: 549513.02 | AT18: -436787.24 | AU18: =SUM(AS18:AT18) -> 112725.78 | AV18: =AU18+AV17 -> 148922.96 | BF18: =AS18 -> 549513.02 | BG18: =AT18 -> -436787.24 | BH18: =AU18 -> 112725.78 | BI18: =AV18 -> 148922.96
C19: 42095 | L19: 238926.06 | M19: 0 | N19: 4948.26 | O19: 148490.04 | AS19: 392364.36 | AT19: -522032.09 | AU19: =SUM(AS19:AT19) -> -129667.73 | AV19: =AU19+AV18 -> 19255.23 | BF19: =AS19 -> 392364.36 | BG19: =AT19 -> -522032.09 | BH19: =AU19 -> -129667.73 | BI19: =AV19 -> 19255.23
C20: 42125 | L20: 276060.96 | M20: 0 | N20: 6834.67 | O20: 296905.35 | AS20: 579800.98 | AT20: -559143.88 | AU20: =SUM(AS20:AT20) -> 20657.1 | AV20: =AU20+AV19 -> 39912.33 | BF20: =AS20 -> 579800.98 | BG20: =AT20 -> -559143.88 | BH20: =AU20 -> 20657.1 | BI20: =AV20 -> 39912.33
C21: 42156 | L21: 314105.92 | M21: 0 | N21: 0 | O21: 195692.3 | AS21: 509798.22 | AT21: -510482.68 | AU21: =SUM(AS21:AT21) -> -684.46 | AV21: =AU21+AV20 -> 39227.87 | BF21: =AS21 -> 509798.22 | BG21: =AT21 -> -510482.68 | BH21: =AU21 -> -684.46 | BI21: =AV21 -> 39227.87
... C56: 43221 | L56: 2028488.2 | M56: 0 | N56: 0 | O56: 31658.19 | AS56: 2060146.4 | AT56: -1991218.4 | AU56: =SUM(AS56:AT56) -> 68927.93 | AV56: =AU56+AV55 -> 169727.35 | BF56: =AS56 -> 2060146.4 | BG56: =AT56 -> -1991218.4 | BH56: =AU56 -> 68927.93 | BI56: =AV56 -> 169727.35
C57: 43252 | L57: 1823384.8 | N57: 0 | O57: 65018.01 | AS57: 1888402.8 | AT57: -1948302.6 | AU57: =SUM(AS57:AT57) -> -59899.81 | AV57: =AU57+AV56 -> 109827.54 | BF57: =AS57 -> 1888402.8 | BG57: =AT57 -> -1948302.6 | BH57: =AU57 -> -59899.81 | BI57: =AV57 -> 109827.54
A58: 1 | C58: 43282 | L58: 2009558.1 | M58: 0 | N58: 0 | O58: -6538.63 | AS58: 2003019.4 | AT58: -1901144.7 | AU58: =SUM(AS58:AT58) -> 101874.77 | AV58: =AU58+AV57 -> 211702.31 | BF58: =AS58 -> 2003019.4 | BG58: =AT58 -> -1901144.7 | BH58: =SUM(BF58:BG58) -> 101874.77 | BI58: =BH58+BI57 -> 211702.31
A59: =A58+1 -> 2 | B59: ACOMPANHAMENTO | C59: 43313 | D59: 0 | E59: 2221975.4 | F59: 0 | G59: 0.1 | H59: =-E59*G59 -> -222197.54 | I59: 0 | L59: =SUM(H59:J59,D59:F59) -> 1999777.9 | P59: -1531774.3 | Q59: -154410.94 | R59: 0 | S59: 0 | T59: 0 | U59: -103903.6 | V59: 0 | W59: -70000 | X59: -5000 | Y59: 0 | Z59: -79994.21 | AA59: -540875.64 | AB59: 0 | AC59: -41454.85 | AD59: -201192 | AE59: -165643.69 | AF59: 0 | AG59: -25711.75 | AH59: =-L1*6% -> -120573.48 | AI59: -9209.81 | AJ59: -7969 | AK59: -10571.835 | AL59: -242823.02 | AM59: =-L1*1.2% -> -24114.697 | AN59: =-L1*4% -> -80382.323 | AO59: 0 | AP59: -24000 | AQ59: 0 | AS59: =+L59 -> 1999777.9 | AT59: =+SUM(P59:AQ59) -> -3439605.1 | AU59: =SUM(AS59:AT59) -> -1439827.2 | AV59: =AU59+AV58 -> -1228124.9 | AX59: 0 | AY59: 0 | AZ59: 0 | BA59: 0 | BB59: 0 | BC59: 0 | BD59: =SUM(AX59:BC59) -> 0 | BE59: 0 | BF59: =L59+AX59+AY59+BA59+BB59 -> 1999777.9 | BG59: =AT59 -> -3439605.1 | BH59: =SUM(BF59:BG59) -> -1439827.2 | BI59: =BH59+BI58 -> -1228124.9
A60: =A59+1 -> 3 | C60: 43344 | D60: 0 | E60: 2238986.8 | F60: 0 | G60: 0.1 | H60: =-E60*G60 -> -223898.68 | I60: 0 | L60: =SUM(H60:J60,D60:F60) -> 2015088.1 | P60: -1514312.9 | Q60: -165440.3 | R60: 0 | S60: 0 | T60: 0 | U60: -103903.6 | V60: 0 | W60: -95321.162 | X60: -5000 | Y60: -26080.141 | Z60: -79994.21 | AA60: -527275.21 | AB60: 0 | AC60: -48379.83 | AD60: -142042 | AE60: -165643.69 | AF60: 0 | AG60: -25711.75 | AH60: =-L59*6% -> -119986.67 | AI60: -9209.81 | AJ60: -7969 | AK60: -12106.458 | AL60: -90637.79 | AM60: =-L59*1.2% -> -23997.335 | AN60: =-L59*4% -> -79991.115 | AO60: 0 | AP60: -24000 | AQ60: -870000 | AS60: =+L60 -> 2015088.1 | AT60: =+SUM(P60:AQ60) -> -4137003 | AU60: =SUM(AS60:AT60) -> -2121914.8 | AV60: =AU60+AV59 -> -3350039.8 | AX60: 15000000 | AY60: 0 | AZ60: 0 | BA60: 0 | BB60: -2263780.1 | BC60: 0 | BD60: =SUM(AX60:BC60) -> 12736220 | BE60: =SUM(AY60:BC60) -> -2263780.1 | BF60: =L60+AX60+AY60+BA60+BB60+BC60+AZ60 -> 14751308 | BG60: =AT60 -> -4137003 | BH60: =SUM(BF60:BG60) -> 10614305 | BI60: =BH60+BI59 -> 9386180.1
A61: =A60+1 -> 4 | C61: 43374 | D61: 0 | E61: 2420664.7 | F61: 0 | G61: 0.1 | H61: =-E61*G61 -> -242066.47 | I61: =-H58 -> 0 | L61: =SUM(H61:J61,D61:F61) -> 2178598.2 | P61: -1766698.4 | Q61: -193013.68 | R61: 0 | S61: 0 | T61: 0 | U61: -103903.6 | V61: 0 | W61: -95321.162 | X61: -5000 | Y61: -43125.711 | Z61: 0 | AA61: -492461.97 | AB61: 0 | AC61: -52259.88 | AD61: -121742 | AE61: -165643.69 | AF61: 0 | AG61: -25711.75 | AH61: =-L60*6% -> -120905.29 | AI61: -9209.81 | AJ61: -7969 | AK61: -12529.674 | AL61: -81235.26 | AM61: =-L60*1.2% -> -24181.058 | AN61: =-L60*4% -> -80603.525 | AO61: 0 | AP61: -1200000 | AS61: =+L61 -> 2178598.2 | AT61: =+SUM(P61:AQ61) -> -4601515.5 | AU61: =SUM(AS61:AT61) -> -2422917.2 | AV61: =AU61+AV60 -> -5772957 | AX61: 0 | AY61: -174843.72 | AZ61: 0 | BA61: -65844.424 | BB61: 0 | BC61: -115000 | BD61: =SUM(AX61:BB61) -> -240688.15 | BE61: =SUM(AY61:BC61) -> -355688.15 | BF61: =L61+AX61+AY61+BA61+BB61+BC61+AZ61 -> 1822910.1 | BG61: =AT61 -> -4601515.5 | BH61: =SUM(BF61:BG61) -> -2778605.3 | BI61: =BH61+BI60 -> 6607574.7
A62: =A61+1 -> 5 | C62: 43405 | D62: 95647.818 | E62: 2455737.2 | F62: 69110.337 | G62: 0.1 | H62: =-E62*G62 -> -245573.72 | I62: =-H59 -> 222197.54 | L62: =SUM(H62:J62,D62:F62) -> 2597119.2 | P62: -1918129.7 | Q62: -209557.71 | R62: 0 | S62: 0 | T62: 0 | U62: -63371 | V62: 0 | W62: -95321.162 | X62: -5000 | Y62: -64289.083 | Z62: 0 | AA62: -482413.39 | AB62: -2213.0871 | AC62: -52498.51 | AD62: -121742 | AE62: -165643.69 | AF62: -29333.333 | AG62: -25711.75 | AH62: =-L61*6% -> -130715.89 | AI62: -9209.81 | AJ62: -7969 | AK62: -13034.914 | AL62: -75391.28 | AM62: =-L61*1.2% -> -26143.179 | AN62: =-L61*4% -> -87143.93 | AO62: 0 | AP62: 0 | AS62: =+L62 -> 2597119.2 | AT62: =+SUM(P62:AQ62) -> -3584832.4 | AU62: =SUM(AS62:AT62) -> -987713.23 | AV62: =AU62+AV61 -> -6760670.2 | AX62: 0 | AY62: -174843.72 | AZ62: 0 | BA62: -67219.924 | BB62: 0 | BC62: -115000 | BD62: =SUM(AX62:BB62) -> -242063.65 | BE62: =SUM(AY62:BC62) -> -357063.65 | BF62: =L62+AX62+AY62+BA62+BB62+BC62+AZ62 -> 2240055.5 | BG62: =AT62 -> -3584832.4 | BH62: =SUM(BF62:BG62) -> -1344776.9 | BI62: =BH62+BI61 -> 5262797.9
A63: =A62+1 -> 6 | C63: 43435 | D63: 150179.71 | E63: 2461625.4 | F63: 69110.337 | G63: 0.1 | H63: =-E63*G63 -> -246162.54 | I63: =-H60 -> 223898.68 | L63: =SUM(H63:J63,D63:F63) -> 2658651.6 | P63: -1918129.7 | Q63: -209557.71 | R63: 0 | S63: 0 | T63: 0 | U63: 0 | V63: 0 | W63: -95321.162 | X63: -5000 | Y63: -77833.579 | Z63: 0 | AA63: -277514.4 | AB63: -3521.7507 | AC63: -52467.32 | AD63: 0 | AE63: -165643.69 | AF63: -46800 | AG63: -25711.75 | AH63: =-L62*6% -> -155827.15 | AI63: -9209.81 | AJ63: -7969 | AK63: -13197.86 | AL63: -66303.71 | AM63: =-L62*1.2% -> -31165.43 | AN63: =-L62*4% -> -103884.77 | AO63: 0 | AP63: 0 | AS63: =+L63 -> 2658651.6 | AT63: =+SUM(P63:AQ63) -> -3265058.8 | AU63: =SUM(AS63:AT63) -> -606407.17 | AV63: =AU63+AV62 -> -7367077.4 | AX63: 0 | AY63: -174843.72 | AZ63: 0 | BA63: -68983.924 | BB63: 0 | BC63: -115000 | BD63: =SUM(AX63:BB63) -> -243827.65 | BE63: =SUM(AY63:BC63) -> -358827.65 | BF63: =L63+AX63+AY63+BA63+BB63+BC63+AZ63 -> 2299824 | BG63: =AT63 -> -3265058.8 | BH63: =SUM(BF63:BG63) -> -965234.82 | BI63: =BH63+BI62 -> 4297563
A64: =A63+1 -> 7 | C64: 43466 | D64: 228130.47 | E64: 2468998.5 | F64: 69110.337 | G64: 0.1 | H64: =-E64*G64 -> -246899.85 | I64: =-H61 -> 242066.47 | L64: =SUM(H64:J64,D64:F64) -> 2761405.9 | P64: -1918129.7 | Q64: -209557.71 | R64: 0 | S64: 0 | T64: 0 | U64: 0 | V64: 0 | W64: -95321.162 | X64: -5000 | Y64: -139983.42 | Z64: 0 | AA64: -254589.19 | AB64: -5218.0243 | AC64: -52490.65 | AD64: 0 | AE64: -165643.69 | AF64: -69200 | AG64: 0 | AH64: =-L63*6% -> -159519.1 | AI64: -9209.81 | AJ64: -7969 | AK64: -13383.092 | AL64: -58596.62 | AM64: =-L63*1.2% -> -31903.819 | AN64: =-L63*4% -> -106346.06 | AO64: 0 | AP64: 0 | AS64: =+L64 -> 2761405.9 | AT64: =+SUM(P64:AQ64) -> -3302061 | AU64: =SUM(AS64:AT64) -> -540655.15 | AV64: =AU64+AV63 -> -7907732.6 | AX64: 27000000 | AY64: -174843.72 | AZ64: 0 | BA64: -70086.424 | BB64: -3591967 | BC64: -115000 | BD64: =SUM(AX64:BB64) -> 23163103 | BE64: =SUM(AY64:BC64) -> -3951897.1 | BF64: =L64+AX64+AY64+BA64+BB64+BC64+AZ64 -> 25809509 | BG64: =AT64 -> -3302061 | BH64: =SUM(BF64:BG64) -> 22507448 | BI64: =BH64+BI63 -> 26805011
A65: =A64+1 -> 8 | C65: 43497 | D65: 273900.62 | E65: 2473272.1 | F65: 69110.337 | G65: 0.1 | H65: =-E65*G65 -> -247327.21 | I65: =-H62 -> 245573.72 | L65: =SUM(H65:J65,D65:F65) -> 2814529.6 | P65: -1918129.7 | Q65: -209557.71 | R65: 0 | S65: 0 | T65: 0 | U65: 0 | V65: 0 | W65: -95321.162 | X65: -5000 | Y65: -178086.84 | Z65: 0 | AA65: -242080.33 | AB65: -6260.6058 | AC65: -52438.46 | AD65: 0 | AE65: -165643.69 | AF65: -83200 | AG65: 0 | AH65: =-L64*6% -> -165684.35 | AI65: -9209.81 | AJ65: -7969 | AK65: -13668.399 | AL65: -51471.91 | AM65: =-L64*1.2% -> -33136.871 | AN65: =-L64*4% -> -110456.24 | AO65: 0 | AP65: 0 | AS65: =+L65 -> 2814529.6 | AT65: =+SUM(P65:AQ65) -> -3347315.1 | AU65: =SUM(AS65:AT65) -> -532785.47 | AV65: =AU65+AV64 -> -8440518 | AX65: 0 | AY65: -174843.72 | AZ65: -314718.7 | BA65: -75535.924 | BB65: 0 | BC65: -115000 | BD65: =SUM(AX65:BB65) -> -565098.34 | BE65: =SUM(AY65:BC65) -> -680098.34 | BF65: =L65+AX65+AY65+BA65+BB65+BC65+AZ65 -> 2134431.3 | BG65: =AT65 -> -3347315.1 | BH65: =SUM(BF65:BG65) -> -1212883.8 | BI65: =BH65+BI64 -> 25592127
A66: =A65+1 -> 9 | C66: 43525 | D66: 513954.33 | E66: 2477068.1 | F66: 69110.337 | G66: 0.1 | H66: =-E66*G66 -> -247706.82 | I66: =-H63 -> 246162.54 | L66: =SUM(H66:J66,D66:F66) -> 3058588.5 | P66: -1918129.7 | Q66: -209557.71 | R66: 0 | S66: 0 | T66: 0 | U66: 0 | V66: 0 | W66: -95321.162 | X66: -5000 | Y66: -196495.61 | Z66: 0 | AA66: -221053.73 | AB66: -11547.709 | AC66: -52361.09 | AD66: 0 | AE66: -165643.69 | AF66: -152400 | AG66: 0 | AH66: =-L65*6% -> -168871.78 | AI66: -9209.81 | AJ66: -7969 | AK66: -13803.312 | AL66: -42786.68 | AM66: =-L65*1.2% -> -33774.355 | AN66: =-L65*4% -> -112581.18 | AO66: 0 | AP66: 0 | AS66: =+L66 -> 3058588.5 | AT66: =+SUM(P66:AQ66) -> -3416506.5 | AU66: =SUM(AS66:AT66) -> -357917.96 | AV66: =AU66+AV65 -> -8798436 | AX66: 0 | AY66: -174843.72 | AZ66: -314718.7 | BA66: -78370.924 | BB66: 0 | BC66: -115000 | BD66: =SUM(AX66:BB66) -> -567933.34 | BE66: =SUM(AY66:BC66) -> -682933.34 | BF66: =L66+AX66+AY66+BA66+BB66+BC66+AZ66 -> 2375655.2 | BG66: =AT66 -> -3416506.5 | BH66: =SUM(BF66:BG66) -> -1040851.3 | BI66: =BH66+BI65 -> 24551276
A67: =A66+1 -> 10 | C67: 43556 | D67: 638500.94 | E67: 2478316.3 | F67: 69110.337 | G67: 0.1 | H67: =-E67*G67 -> -247831.63 | I67: =-H64 -> 246899.85 | L67: =SUM(H67:J67,D67:F67) -> 3184995.8 | P67: -1918129.7 | Q67: -209557.71 | R67: 0 | S67: 0 | T67: 0 | U67: 0 | V67: 0 | W67: -95321.162 | X67: -5000 | Y67: -201655.71 | Z67: 0 | AA67: -176529.34 | AB67: -14607.654 | AC67: -52371.73 | AD67: 0 | AE67: -165643.69 | AF67: -193200 | AG67: 0 | AH67: =-L66*6% -> -183515.31 | AI67: -9209.81 | AJ67: -23969 | AK67: -14069.046 | AL67: -40237.62 | AM67: =-L66*1.2% -> -36703.063 | AN67: =-L66*4% -> -122343.54 | AO67: -10000 | AP67: 0 | AS67: =+L67 -> 3184995.8 | AT67: =+SUM(P67:AQ67) -> -3472064.1 | AU67: =SUM(AS67:AT67) -> -287068.25 | AV67: =AU67+AV66 -> -9085504.2 | AX67: 0 | AY67: -174843.72 | AZ67: -314718.7 | BA67: -79945.924 | BB67: 0 | BC67: -115000 | BD67: =SUM(AX67:BB67) -> -569508.34 | BE67: =SUM(AY67:BC67) -> -684508.34 | BF67: =L67+AX67+AY67+BA67+BB67+BC67+AZ67 -> 2500487.5 | BG67: =AT67 -> -3472064.1 | BH67: =SUM(BF67:BG67) -> -971576.59 | BI67: =BH67+BI66 -> 23579699
A68: =A67+1 -> 11 | C68: 43586 | D68: 725772.28 | E68: 2477298.6 | F68: 69110.337 | G68: 0.1 | H68: =-E68*G68 -> -247729.86 | I68: =-H65 -> 247327.21 | L68: =SUM(H68:J68,D68:F68) -> 3271778.6 | P68: -1918129.7 | Q68: -209557.71 | R68: 0 | S68: 0 | T68: 0 | U68: 0 | V68: 0 | W68: -95321.162 | X68: -5000 | Y68: -212904.69 | Z68: 0 | AA68: -161299.94 | AB68: -16136.347 | AC68: -52329.99 | AD68: 0 | AE68: -165643.69 | AF68: -183866.67 | AG68: 0 | AH68: =-L67*6% -> -191099.75 | AI68: -9209.81 | AJ68: -23969 | AK68: -14677.487 | AL68: -34414.14 | AM68: =-L67*1.2% -> -38219.95 | AN68: =-L67*4% -> -127399.83 | AO68: 0 | AP68: 0 | AS68: =+L68 -> 3271778.6 | AT68: =+SUM(P68:AQ68) -> -3459179.9 | AU68: =SUM(AS68:AT68) -> -187401.29 | AV68: =AU68+AV67 -> -9272905.5 | AX68: 0 | AY68: -174843.72 | AZ68: -314718.7 | BA68: -80418.424 | BB68: 0 | BC68: -115000 | BD68: =SUM(AX68:BB68) -> -569980.84 | BE68: =SUM(AY68:BC68) -> -684980.84 | BF68: =L68+AX68+AY68+BA68+BB68+BC68+AZ68 -> 2586797.7 | BG68: =AT68 -> -3459179.9 | BH68: =SUM(BF68:BG68) -> -872382.13 | BI68: =BH68+BI67 -> 22707317
A69: =A68+1 -> 12 | C69: 43617 | D69: 745105.49 | E69: 2477603.4 | F69: 69110.337 | G69: 0.1 | H69: =-E69*G69 -> -247760.34 | I69: =-H66 -> 247706.82 | L69: =SUM(H69:J69,D69:F69) -> 3291765.7 | P69: -1918129.7 | Q69: -209557.71 | R69: -972900 | S69: 0 | T69: -60000 | U69: 0 | V69: 0 | W69: -95321.162 | X69: -5000 | Y69: -226806.18 | Z69: 0 | AA69: -139008.52 | AB69: -16590.477 | AC69: -52350.45 | AD69: 0 | AE69: 0 | AF69: -172400 | AG69: 0 | AH69: =-L68*6% -> -196306.71 | AI69: -9209.81 | AJ69: -7969 | AK69: -15097.477 | AL69: -29838.75 | AM69: =-L68*1.2% -> -39261.343 | AN69: =-L68*4% -> -130871.14 | AO69: 0 | AP69: 0 | AQ69: 0 | AS69: =+L69 -> 3291765.7 | AT69: =+SUM(P69:AQ69) -> -4296618.4 | AU69: =SUM(AS69:AT69) -> -1004852.7 | AV69: =AU69+AV68 -> -10277758 | AX69: 0 | AY69: -174843.72 | AZ69: -314718.7 | BA69: -81468.424 | BB69: 0 | BC69: -115000 | BD69: =SUM(AX69:BB69) -> -571030.84 | BE69: =SUM(AY69:BC69) -> -686030.84 | BF69: =L69+AX69+AY69+BA69+BB69+BC69+AZ69 -> 2605734.9 | BG69: =AT69 -> -4296618.4 | BH69: =SUM(BF69:BG69) -> -1690883.5 | BI69: =BH69+BI68 -> 21016433
A70: =A69+1 -> 13 | C70: 43647 | D70: 787321.33 | E70: 2478692.8 | F70: 69110.337 | G70: 0.1 | H70: =-E70*G70 -> -247869.28 | I70: =-H67 -> 247831.63 | L70: =SUM(H70:J70,D70:F70) -> 3335086.8 | P70: -1918129.7 | Q70: -209557.71 | R70: -1280592.3 | S70: 0 | T70: -60000 | U70: 0 | V70: 0 | W70: -95321.162 | X70: -2000 | Y70: -244996.4 | Z70: 0 | AA70: -108182.15 | AB70: -17601.078 | AC70: -52367.49 | AD70: 0 | AE70: 0 | AF70: -163333.33 | AG70: 0 | AH70: =-L69*6% -> -197505.94 | AI70: -9209.81 | AJ70: -7969 | AK70: -15746.698 | AL70: -26964.79 | AM70: =-L69*1.2% -> -39501.189 | AN70: =-L69*4% -> -131670.63 | AO70: 0 | AP70: 0 | AQ70: 0 | AS70: =+L70 -> 3335086.8 | AT70: =+SUM(P70:AQ70) -> -4580649.4 | AU70: =SUM(AS70:AT70) -> -1245562.6 | AV70: =AU70+AV69 -> -11523321 | AX70: 0 | AY70: -174843.72 | AZ70: -314718.7 | BA70: -82780.924 | BB70: 0 | BC70: -115000 | BD70: =SUM(AX70:BB70) -> -572343.34 | BE70: =SUM(AY70:BC70) -> -687343.34 | BF70: =L70+AX70+AY70+BA70+BB70+BC70+AZ70 -> 2647743.4 | BG70: =AT70 -> -4580649.4 | BH70: =SUM(BF70:BG70) -> -1932905.9 | BI70: =BH70+BI69 -> 19083527
A71: =A70+1 -> 14 | C71: 43678 | D71: 839906.23 | E71: 2478928.9 | F71: 69110.337 | G71: 0.1 | H71: =-E71*G71 -> -247892.89 | I71: =-H68 -> 247729.86 | L71: =SUM(H71:J71,D71:F71) -> 3387782.4 | P71: -1918129.7 | Q71: -209557.71 | R71: -1280592.3 | S71: 0 | T71: -60000 | U71: 0 | V71: 0 | W71: -95321.162 | X71: -2000 | Y71: -296425.66 | Z71: 0 | AA71: -87692.41 | AB71: -18873.923 | AC71: -52300.54 | AD71: 0 | AE71: 0 | AF71: -166000 | AG71: 0 | AH71: =-L70*6% -> -200105.21 | AI71: -9209.81 | AJ71: -7969 | AK71: -16317.504 | AL71: -24397.08 | AM71: =-L70*1.2% -> -40021.041 | AN71: =-L70*4% -> -133403.47 | AO71: 0 | AP71: 0 | AQ71: 0 | AS71: =+L71 -> 3387782.4 | AT71: =+SUM(P71:AQ71) -> -4618316.5 | AU71: =SUM(AS71:AT71) -> -1230534.1 | AV71: =AU71+AV70 -> -12753855 | AX71: 0 | AY71: -174843.72 | AZ71: -314718.7 | BA71: -84355.924 | BB71: 0 | BC71: -115000 | BD71: =SUM(AX71:BB71) -> -573918.34 | BE71: =SUM(AY71:BC71) -> -688918.34 | BF71: =L71+AX71+AY71+BA71+BB71+BC71+AZ71 -> 2698864.1 | BG71: =AT71 -> -4618316.5 | BH71: =SUM(BF71:BG71) -> -1919452.4 | BI71: =BH71+BI70 -> 17164075
A72: =A71+1 -> 15 | C72: 43709 | D72: 908649.16 | E72: 2478205.6 | F72: 69110.337 | G72: 0.1 | H72: =-E72*G72 -> -247820.56 | I72: =-H69 -> 247760.34 | L72: =SUM(H72:J72,D72:F72) -> 3455904.9 | P72: -1918129.7 | Q72: -209557.71 | R72: -1280592.3 | S72: -100000 | T72: -60000 | U72: 0 | V72: -40882.573 | W72: -95321.162 | X72: -2000 | Y72: -303432.29 | Z72: 0 | AA72: -68833.8 | AB72: -20402.616 | AC72: -52294.81 | AD72: 0 | AE72: 0 | AF72: -116800 | AG72: 0 | AH72: =-L71*6% -> -203266.95 | AI72: -9209.81 | AJ72: -7969 | AK72: -16466.781 | AL72: -22365.19 | AM72: =-L71*1.2% -> -40653.389 | AN72: =-L71*4% -> -135511.3 | AO72: 0 | AP72: 0 | AQ72: 0 | AS72: =+L72 -> 3455904.9 | AT72: =+SUM(P72:AQ72) -> -4703689.4 | AU72: =SUM(AS72:AT72) -> -1247784.5 | AV72: =AU72+AV71 -> -14001639 | AX72: 0 | AY72: -174843.72 | AZ72: -314718.7 | BA72: -106112.68 | BB72: 0 | BC72: -115000 | BD72: =SUM(AX72:BB72) -> -595675.1 | BE72: =SUM(AY72:BC72) -> -710675.1 | BF72: =L72+AX72+AY72+BA72+BB72+BC72+AZ72 -> 2745229.8 | BG72: =AT72 -> -4703689.4 | BH72: =SUM(BF72:BG72) -> -1958459.6 | BI72: =BH72+BI71 -> 15205615
A73: =A72+1 -> 16 | C73: 43739 | D73: 1102815.9 | E73: 2473443.2 | F73: 69110.337 | G73: 0.1 | H73: =-E73*G73 -> -247344.32 | I73: =-H70 -> 247869.28 | L73: =SUM(H73:J73,D73:F73) -> 3645894.4 | P73: -1918129.7 | Q73: -209557.71 | R73: -1280592.3 | S73: -100000 | T73: -60000 | U73: 0 | V73: -40882.573 | W73: -95321.162 | X73: -2000 | Y73: -316118.04 | Z73: 0 | AA73: 0 | AB73: -24589.572 | AC73: -52223.05 | AD73: 0 | AE73: 0 | AF73: -130800 | AG73: 0 | AH73: =-L72*6% -> -207354.29 | AI73: -9209.81 | AJ73: -7969 | AK73: -16646.083 | AL73: -19689.79 | AM73: =-L72*1.2% -> -41470.858 | AN73: =-L72*4% -> -138236.19 | AO73: 0 | AP73: 0 | AQ73: 0 | AS73: =+L73 -> 3645894.4 | AT73: =+SUM(P73:AQ73) -> -4670790.1 | AU73: =SUM(AS73:AT73) -> -1024895.7 | AV73: =AU73+AV72 -> -15026535 | AX73: 0 | AY73: -174843.72 | AZ73: -314718.7 | BA73: -92356.924 | BB73: 0 | BC73: -115000 | BD73: =SUM(AX73:BB73) -> -581919.34 | BE73: =SUM(AY73:BC73) -> -696919.34 | BF73: =L73+AX73+AY73+BA73+BB73+BC73+AZ73 -> 2948975.1 | BG73: =AT73 -> -4670790.1 | BH73: =SUM(BF73:BG73) -> -1721815.1 | BI73: =BH73+BI72 -> 13483800
A74: =A73+1 -> 17 | C74: 43770 | D74: 1128741.5 | E74: 2472474.6 | F74: 69110.337 | G74: 0.1 | H74: =-E74*G74 -> -247247.46 | I74: =-H71 -> 247892.89 | L74: =SUM(H74:J74,D74:F74) -> 3670971.9 | P74: -1918129.7 | Q74: -209557.71 | R74: -1037367.3 | S74: -100000 | T74: -60000 | U74: 0 | V74: -40882.573 | W74: -95321.162 | X74: -2000 | Y74: -313641.88 | Z74: 0 | AA74: 0 | AB74: -25307.226 | AC74: -52191.13 | AD74: 0 | AE74: 0 | AF74: -120400 | AG74: 0 | AH74: =-L73*6% -> -218753.66 | AI74: -9209.81 | AJ74: -7969 | AK74: -16934.841 | AL74: -18481.86 | AM74: =-L73*1.2% -> -43750.733 | AN74: =-L73*4% -> -145835.78 | AO74: 0 | AP74: 0 | AQ74: 0 | AS74: =+L74 -> 3670971.9 | AT74: =+SUM(P74:AQ74) -> -4435734.4 | AU74: =SUM(AS74:AT74) -> -764762.51 | AV74: =AU74+AV73 -> -15791298 | AX74: 0 | AY74: -174843.72 | AZ74: -314718.7 | BA74: -94656.424 | BB74: 0 | BC74: -115000 | BD74: =SUM(AX74:BB74) -> -584218.84 | BE74: =SUM(AY74:BC74) -> -699218.84 | BF74: =L74+AX74+AY74+BA74+BB74+BC74+AZ74 -> 2971753 | BG74: =AT74 -> -4435734.4 | BH74: =SUM(BF74:BG74) -> -1463981.3 | BI74: =BH74+BI73 -> 12019819
...

Sheet Indicadores
B3: RESULTADO SEM ALAVANCAGEM | K3: RESULTADO COM ALAVANCAGEM | T3: DIFERENÇA
B4: Receita | F4: ='Fluxo Consolidado'!L3 -> 3.6941881e+08 | K4: Receita | O4: =+F4 -> 3.6941881e+08 | T4: =+O4-F4 -> 0
B5: Emprestimo | F5: ='Fluxo Consolidado'!M3+'Fluxo Consolidado'!N3 -> 2493512 | K5: Emprestimo | O5: =+F5 -> 2493512 | T5: =+O5-F5 -> 0
B6: Despesa | F6: ='Fluxo Consolidado'!AT3 -> -1.6981533e+08 | K6: Despesa | O6: ='Fluxo Consolidado'!BG3+'Fluxo Consolidado'!BD3 -> -2.150893e+08 | T6: =+O6-F6 -> -45273972
B7: Resultado | F7: =+F4+F6+F5 -> 2.0209699e+08 | K7: Resultado | O7: =SUM(O4:R6) -> 1.5682302e+08 | T7: =+O7-F7 -> -45273972
B8: Exposição Máxima | F8: =MIN('Fluxo Consolidado'!AV59:AV186) -> -16571542 | K8: Exposição Máxima | O8: =MIN('Fluxo Consolidado'!BI59:BI186) -> -1228124.9 | T8: =+O8-F8 -> 15343417
B9: Dt. Exposição Máxima | F9: ='Fluxo Consolidado'!C75 -> 43800 | K9: Dt. Exposição Máxima | O9: ='Fluxo Consolidado'!C59 -> 43313 | T9: =+(O9-F9)/30 -> -16.233333
B10: PayBack | F10: ='Fluxo Consolidado'!C84 -> 44075 | K10: PayBack | O10: ='Fluxo Consolidado'!C60 -> 43344 | T10: =+(O10-F10)/30 -> -24.366667
B11: TIR (a.m. | a.a.) | F11: ='DRE - Grafico'!L35 -> 0.028510764 | H11: =(1+F11)^12-1 -> 0.40121924 | K11: TIR (a.m. | a.a.) | O11: ='DRE - Grafico'!L40 -> 0.030839069 | Q11: =(1+O11)^12-1 -> 0.43976112
B12: Margem (Resul. / Receita) | F12: =F7/F4 -> 0.54706741 | K12: Margem (Resul. / Receita) | O12: =O7/O4 -> 0.42451282 | T12: =+O12-F12 -> -0.12255459
B13: ROE (Resul. / Exp. Máx.) | F13: =F7/-F8 -> 12.195425 | K13: ROE (Resul. / Exp. Máx.) | O13: =O7/-O8 -> 127.69305 | T13: =+O13-F13 -> 115.49763
B15: FLUXO ANUAL DO EMPREENIDMENTO
B30: FLUXO ANUAL DO EMPREENIDMENTO
B31: ANO | F31: SEM ALAVANCAGEM | L31: COM ALAVANCAGEM
B32: 2012 | F32: 0 | L32: 0
B33: =B32+1 -> 2013 | F33: 0 | L33: 0
B34: =B33+1 -> 2014 | F34: ='Resumo Ano'!E6 -> 68299.79 | L34: ='Resumo Ano'!K6 -> 68299.79
B35: =B34+1 -> 2015 | F35: ='Resumo Ano'!E7 -> -13246.93 | L35: ='Resumo Ano'!K7 -> -13246.93
B36: =B35+1 -> 2016 | F36: ='Resumo Ano'!E8 -> 42146.14 | L36: ='Resumo Ano'!K8 -> 42146.14
B37: =B36+1 -> 2017 | F37: ='Resumo Ano'!E9 -> -27785.75 | L37: ='Resumo Ano'!K9 -> -27785.75
B38: =B37+1 -> 2018 | F38: ='Resumo Ano'!E10 -> -7436490.6 | L38: ='Resumo Ano'!K10 -> 4573149.8
B39: =B38+1 -> 2019 | F39: ='Resumo Ano'!E11 -> -9204464.5 | L39: ='Resumo Ano'!K11 -> 7625157.6
B40: =B39+1 -> 2020 | F40: ='Resumo Ano'!E12 -> 26678325 | L40: ='Resumo Ano'!K12 -> 18545153
B41: =B40+1 -> 2021 | F41: ='Resumo Ano'!E13 -> 40254086 | L41: ='Resumo Ano'!K13 -> 28924881
B42: =B41+1 -> 2022 | F42: ='Resumo Ano'!E14 -> 39707620 | L42: ='Resumo Ano'!K14 -> 29280302
B43: =B42+1 -> 2023 | F43: ='Resumo Ano'!E15 -> 38226745 | L43: ='Resumo Ano'!K15 -> 28652409
B44: =B43+1 -> 2024 | F44: ='Resumo Ano'!E16 -> 36479903 | L44: ='Resumo Ano'!K16 -> 27723921
B45: =B44+1 -> 2025 | F45: ='Resumo Ano'!E17 -> 27624713 | L45: ='Resumo Ano'!K17 -> 19662563
... B50: =B49+1 -> 2030 | F50: ='Resumo Ano'!E22 -> 0 | L50: ='Resumo Ano'!K22 -> 0
B51: TOTAL | F51: =SUM(F32:K50) -> 2.0563692e+08 | L51: =SUM(L32:R50) -> 1.6036295e+08

Sheet Fluxo - Com Terreno
D1: =+D8+E8+F8+G8 -> 8142 | T1: 1 | AA1: 542145.24 | AH1: 0 | AJ1: -1400 | AN1: =+AN8/AN4 -> #DIV/0! | AP1: =+#REF!*0.5% -> #REF! | AY1: 0.04 | BW1: =IRR(BW64:BW189,1%) -> #VALUE! | BX1: TAXA ALL IN MÊS
AP2: 25 | AQ2: -0.06 | AW2: 0.012 | AY2: 0.0673
A4: VERIFICAÇÃO | T4: 0 | BL4: =BL8-BF8 -> 0 | BM4: =BM8-BG8 -> #REF! | BN4: =BN8-BH8 -> #REF! | BW4: =(1+BW1)^12-1 -> #VALUE! | BX4: TAXA ALL IN ANO
G5: =+G8+F8+E8+D8 -> 8142 | V5: =+V8+T8 -> 3.6716603e+08 | Y5: =+V5+Y8 -> 3.7071246e+08 | AN5: 0.035 | CE5: 0.01
CB6: =MIN(CB64:CB190) -> #REF! | CC6: =MIN(CC64:CC190) -> #REF!
D7: VELOCIDADE DE VENDA | K7: RECEITA | Z7: OBRA | AJ7: COMERCIALIZAÇÃO | AQ7: ADMINISTRATIVO | AV7: DISTRATO DE VENDA | AW7: DESPESAS BANCÁRIAS | AX7: AQUISIÇÃO DO TERRENO | AY7: IMPOSTOS | AZ7: OUTRAS DESPESAS | BF7: RESUMO SEM ALAVANCAGEM | BK7: RESUMO ANO SEM ALAVANCAGEM | BQ7: FLUXO CRI | BY7: RESUMO COM ALAVANCAGEM | CE7: FLUXO A VP
A8: CRONOGRAMA | D8: =SUM(D10:D190) -> 2005 | E8: =SUM(E10:E190) -> 3964 | F8: =SUM(F10:F190) -> 728 | G8: =SUM(G10:G190) -> 1445 | H8: =SUM(H10:H190) -> 1.2860081e+08 | I8: =SUM(I10:I190) -> 34610760 | J8: =SUM(J10:J190) -> 1.4726964e+08 | K8: =SUM(K10:K190) -> 1.0904974e+08 | ... N8: =SUM(N10:N190) -> 42199126 | P8: =SUM(P10:P190) -> -11265591 | Q8: =SUM(Q10:Q190) -> 11265591 | R8: 0.005 | T8: =SUM(T10:T190) -> -243226.04 | V8: =SUM(V10:V190) -> 3.6740925e+08 | W8: =SUM(W10:W190) -> 1000000 | X8: =SUM(X10:X190) -> 1493512 | Y8: =SUM(Y10:Y190) -> 3546437.8 | Z8: =SUM(Z10:Z190) -> 1 | AA8: =SUM(AA10:AA190) -> -542145.24 | AB8: =SUM(AB10:AB190) -> -50570768 | AC8: =SUM(AC10:AC190) -> -3617594.9 | ... AZ8: =SUM(AZ10:AZ190) -> -174962.81 | BB8: =SUM(BB10:BB190) -> -16649.28 | BC8: =SUM(BC10:BC190) -> -1416300 | BD8: =SUM(BD10:BD190) -> -1290090.5 | BF8: =SUM(BF10:BF190) -> 3.734492e+08 | BG8: =SUM(BG10:BG190) -> #REF! | BH8: =SUM(BH10:BH190) -> #REF! | BL8: =SUM(BL10:BL28) -> 3.734492e+08 | BM8: =SUM(BM10:BM28) -> #REF! | BN8: =+BL8+BM8 -> #REF! | BQ8: =SUM(BQ10:BQ190) -> 45000000 | BR8: =SUM(BR10:BR190) -> #REF! | BS8: =SUM(BS10:BS190) -> -5183823.9 | BT8: =SUM(BT10:BT190) -> -5878257.8 | BU8: =SUM(BU10:BU190) -> -3.2287682e+08 | BV8: =SUM(BV10:BV190) -> 3.1987682e+08 | BW8: =SUM(BW10:BW190) -> #REF! | BX8: =SUM(BX10:BX190) -> #REF! | ... CA8: =SUM(CA10:CA190) -> #REF! | CE8: =SUM(CE10:CE190) -> #REF! | CF8: =SUM(CF10:CF190) -> #REF!
A9: N° | B9: EVENTO | C9: MESES | D9: Cotas 1/4 (2*) | E9: Cotas 1/4 (3*) | F9: Cotas 2/4 (2*) | G9: Cotas 2/4 (3*) | H9: VGV REALIZADO 3 SEMANA | I9: VGV REALIZADO 2 SEMANA | J9: VGV ESTOQUE | K9: ESTOQUE | L9: AGING DA CARTERIA | M9: RECUPERAÇÃO INADIMPLÊNCIA AGING | N9: RECEBIDO | O9: INADIMPLÊNCIA | Q9: RECUPERAÇÃO | R9: CORREÇÃO 0,5% | T9: JUROS /DESCONTO | V9: RECEITA TOTAL | W9: EMPRESTIMO PF | X9: EMP. MUTUO ENTRE EMPRESAS | Y9: OUTRAS ENTRADAS | Z9: % | AA9: AREA ANEXA | AB9: CRONOGRAMA OBRA | AC9: TAXA DE ADMINISTRAÇÃO | AD9: FF&E | AE9: INFRAESTRUTURA | AF9: PARQUE AQ. | AG9: PROJETO | AH9: LEGALIZAÇÃO OBRA | AI9: GERENCIAMENTO OBRA | AJ9: VENDAS GERAL | AK9: APTO MODELO | AL9: COMISSÃO WAM | AM9: CLUB CIA | AN9: FÉRIAS CLUB | AO9: PASSAPORTE | AP9: MARKETING | AQ9: GESTÃO DA CARTEIRA | AR9: HONORÁRIOS ADV | AS9: HONORÁRIOS CONTABEIS / AUDITORIA | AT9: CUSTO CARTORIO / TAXAS E REGISTROS | AU9: CORRESPONDÊNCIA E MALOTE | AV9: DISTRATO DE VENDA | AW9: DESPESAS BANCÁRIAS | AX9: AQUISIÇÃO DO TERRENO | AY9: IMPOSTOS | AZ9: DEPOSITO JUDICIAL | BA9: DISTRIBUIÇÃO | BB9: OUTRAS DESPESAS | BC9: EMPRESTIMO EMPRESAS LIGADAS E PF - PJ | BD9: EMP. MUTUO ENTRE EMPRESAS | BF9: TOTAL RECEITA | BG9: TOTAL DESPESAS | BH9: SALDO MENSAL | BI9: SALDO ACUMULADO | BK9: ANO | BL9: TOTAL RECEITA | BM9: TOTAL DESPESAS | BN9: SALDO MENSAL | BO9: SALDO ACUMULADO | BQ9: LIBERAÇÃO DAS TRANCHES CONFORME MEDIÇÃO DE OBRA | BR9: PMT (AMORTIZAÇÃO + JUROS) | BS9: DESPESAS RECORRENTES / DESPESAS GESTÃO | BT9: CUSTOS FLAT - ESTRUTURAÇÃO | BU9: DEVOLUÇÃO DA CARTEIRA | BV9: DEVOLUÇÃO DO EXCEDENTE | BW9: FLUXO MENSAL ECONOMICO | BX9: FLUXO MENSAL FINANCEIRO | BY9: TOTAL RECEITA | BZ9: TOTAL DESPESAS | CA9: SALDO MENSAL | CB9: FLUXO ACUMULADO | CE9: FLUXO SEM CRI | CF9: FLUXO COM CRI
A10: 0 | C10: 41671 | D10: 0 | E10: 0 | F10: 0 | G10: 0 | H10: 0 | I10: 0 | J10: 0 | K10: 0 | L10: 0 | M10: 0 | N10: 0 | O10: 0 | P10: 0 | Q10: 0 | T10: 0 | V10: =SUM(P10:T10,K10:N10) -> 0 | W10: 0 | X10: 0 | Y10: 1000 | Z10: =IFERROR(SUM(AA10:AH10)/SUM($AA$8:$AH$8),0) -> 0 | AA10: 0 | AB10: 0 | AD10: 0 | AE10: 0 | AG10: 0 | AH10: 0 | AI10: 0 | AJ10: 0 | AK10: 0 | AL10: 0 | AM10: 0 | AN10: 0 | AO10: 0 | AP10: 0 | AQ10: 0 | AR10: 0 | AS10: 0 | AT10: 0 | AU10: 0 | AV10: 0 | AW10: 0 | AX10: -3900000 | AY10: 0 | AZ10: 0 | BA10: 0 | BB10: 0 | BC10: 0 | BD10: 0 | BF10: =V10+Y10+W10+X10 -> 1000 | BG10: =+SUM(AA10:BD10) -> -3900000 | BH10: =SUM(BF10:BG10) -> -3899000 | BI10: =+BH10 -> -3899000 | BJ10: =+BI10-$AX$8 -> 3127198.5 | BK10: 2014 | BL10: =SUMIFS($BF$10:$BF$208,$C$10:$C$208,">="&DATE(BK10,1,1),$C$10:$C$208,"<="&DATE(BK10,12,31)) -> 1964634 | BM10: =SUMIFS($BG$10:$BG$208,$C$10:$C$208,">="&DATE(BK10,1,1),$C$10:$C$208,"<="&DATE(BK10,12,31)) -> -8922532.7 | BN10: =SUM(BL10:BM10) -> -6957898.8 | BO10: =BN10 -> -6957898.8 | BQ10: 0 | BR10: 0 | BS10: 0 | BT10: 0 | BU10: 0 | BW10: =SUM(BQ10:BU10) -> 0 | BX10: 0 | BY10: =BF10 -> 1000 | BZ10: =BG10 -> -3900000 | CA10: =BH10 -> -3899000 | CB10: =BI10 -> -3899000 | CE10: =PV($CE$5,A10,,-BH10) -> -3899000 | CF10: =PV($CE$5,A10,,-CA10) -> -3899000
A11: 0 | C11: 41699 | D11: 0 | E11: 0 | F11: 0 | G11: 0 | H11: 0 | I11: 0 | J11: 0 | K11: 0 | L11: 0 | M11: 0 | N11: 0 | O11: 0 | P11: 0 | Q11: 0 | T11: 0 | V11: =SUM(P11:T11,K11:N11) -> 0 | W11: 0 | X11: 0 | Y11: 0 | Z11: =IFERROR(SUM(AA11:AH11)/SUM($AA$8:$AH$8),0) -> 0 | AA11: 0 | AB11: 0 | AD11: 0 | AE11: 0 | AG11: 0 | AH11: 0 | AI11: 0 | AJ11: 0 | AK11: 0 | AL11: 0 | AM11: 0 | AN11: 0 | AO11: 0 | AP11: 0 | AQ11: 0 | AR11: 0 | AS11: 0 | AT11: 0 | AU11: 0 | AV11: 0 | AW11: 0 | AX11: 0 | AY11: 0 | AZ11: 0 | BA11: 0 | BB11: 0 | BC11: 0 | BD11: 0 | BF11: =V11+Y11+W11+X11 -> 0 | BG11: =+SUM(AA11:BD11) -> 0 | BH11: =SUM(BF11:BG11) -> 0 | BI11: =BH11+BI10 -> -3899000 | BJ11: =+BI11-$AX$8 -> 3127198.5 | BK11: 2015 | BL11: =SUMIFS($BF$10:$BF$208,$C$10:$C$208,">="&DATE(BK11,1,1),$C$10:$C$208,"<="&DATE(BK11,12,31)) -> 5679311.6 | BM11: =SUMIFS($BG$10:$BG$208,$C$10:$C$208,">="&DATE(BK11,1,1),$C$10:$C$208,"<="&DATE(BK11,12,31)) -> -5692558.5 | BN11: =SUM(BL11:BM11) -> -13246.93 | BO11: =+BN11+BO10 -> -6971145.7 | BQ11: 0 | BR11: 0 | BS11: 0 | BT11: 0 | BU11: 0 | BW11: =SUM(BQ11:BT11) -> 0 | BX11: 0 | BY11: =BF11 -> 0 | BZ11: =BG11 -> 0 | CA11: =BH11 -> 0 | CB11: =BI11 -> -3899000 | CE11: =PV($CE$5,A11,,-BH11) -> 0 | CF11: =PV($CE$5,A11,,-CA11) -> 0
A12: 0 | C12: 41730 | D12: 0 | E12: 0 | F12: 0 | G12: 0 | H12: 0 | I12: 0 | J12: 0 | K12: 0 | L12: 0 | M12: 0 | N12: 0 | O12: 0 | P12: 0 | Q12: 0 | T12: 0 | V12: =SUM(P12:T12,K12:N12) -> 0 | W12: 0 | X12: 0 | Y12: 9245.14 | Z12: =IFERROR(SUM(AA12:AH12)/SUM($AA$8:$AH$8),0) -> 0.00010590902 | AA12: 0 | AB12: -547.69 | AD12: 0 | AE12: 0 | AG12: 0 | AH12: -7130.41 | AI12: 0 | AJ12: 0 | AK12: -1567.04 | AL12: 0 | AM12: 0 | AN12: 0 | AO12: 0 | AP12: 0 | AQ12: 0 | AR12: 0 | AS12: 0 | AT12: 0 | AU12: 0 | AV12: 0 | AW12: 0 | AX12: -1550000 | AY12: 0 | AZ12: 0 | BA12: 0 | BB12: 0 | BC12: 0 | BD12: 0 | BF12: =V12+Y12+W12+X12 -> 9245.14 | BG12: =+SUM(AA12:BD12) -> -1559245.1 | BH12: =SUM(BF12:BG12) -> -1550000 | BI12: =BH12+BI11 -> -5449000 | BJ12: =+BI12-$AX$8 -> 1577198.5 | BK12: 2016 | BL12: =SUMIFS($BF$10:$BF$208,$C$10:$C$208,">="&DATE(BK12,1,1),$C$10:$C$208,"<="&DATE(BK12,12,31)) -> 10104711 | BM12: =SUMIFS($BG$10:$BG$208,$C$10:$C$208,">="&DATE(BK12,1,1),$C$10:$C$208,"<="&DATE(BK12,12,31)) -> -10062564 | BN12: =SUM(BL12:BM12) -> 42146.14 | BO12: =BN12+BO11 -> -6928999.5 | BQ12: 0 | BR12: 0 | BS12: 0 | BT12: 0 | BU12: 0 | BW12: =SUM(BQ12:BT12) -> 0 | BX12: 0 | BY12: =BF12 -> 9245.14 | BZ12: =BG12 -> -1559245.1 | CA12: =BH12 -> -1550000 | CB12: =BI12 -> -5449000 | CE12: =PV($CE$5,A12,,-BH12) -> -1550000 | CF12: =PV($CE$5,A12,,-CA12) -> -1550000
A13: 0 | C13: 41760 | D13: 0 | E13: 0 | F13: 0 | G13: 0 | H13: 0 | I13: 0 | J13: 0 | K13: 0 | L13: 0 | M13: 0 | N13: 0 | O13: 0 | P13: 0 | Q13: 0 | T13: 0 | V13: =SUM(P13:T13,K13:N13) -> 0 | W13: 0 | X13: 46553.47 | Y13: 146407.45 | Z13: =IFERROR(SUM(AA13:AH13)/SUM($AA$8:$AH$8),0) -> 0.0015025763 | AA13: 0 | AB13: -43 | AD13: 0 | AE13: 0 | AG13: -19866.8 | AH13: -89022.67 | AI13: 0 | AJ13: 0 | AK13: -31126.25 | AL13: 0 | AM13: 0 | AN13: 0 | AO13: 0 | AP13: 0 | AQ13: 0 | AR13: 0 | AS13: 0 | AT13: 0 | AU13: 0 | AV13: 0 | AW13: -1700.03 | AX13: 0 | AY13: 0 | AZ13: 0 | BA13: 0 | BB13: 0 | BC13: 0 | BD13: -46553.47 | BF13: =V13+Y13+W13+X13 -> 192960.92 | BG13: =+SUM(AA13:BD13) -> -188312.22 | BH13: =SUM(BF13:BG13) -> 4648.7 | BI13: =BH13+BI12 -> -5444351.3 | BJ13: =+BI13-$AX$8 -> 1581847.2 | BK13: 2017 | BL13: =SUMIFS($BF$10:$BF$208,$C$10:$C$208,">="&DATE(BK13,1,1),$C$10:$C$208,"<="&DATE(BK13,12,31)) -> 19056114 | BM13: =SUMIFS($BG$10:$BG$208,$C$10:$C$208,">="&DATE(BK13,1,1),$C$10:$C$208,"<="&DATE(BK13,12,31)) -> -19083900 | BN13: =SUM(BL13:BM13) -> -27785.75 | BO13: =BN13+BO12 -> -6956785.3 | BQ13: 0 | BR13: 0 | BS13: 0 | BT13: 0 | BU13: 0 | BW13: =SUM(BQ13:BT13) -> 0 | BX13: 0 | BY13: =BF13 -> 192960.92 | BZ13: =BG13 -> -188312.22 | CA13: =BH13 -> 4648.7 | CB13: =BI13 -> -5444351.3 | CE13: =PV($CE$5,A13,,-BH13) -> 4648.7 | CF13: =PV($CE$5,A13,,-CA13) -> 4648.7
A14: 0 | C14: 41791 | D14: 0 | E14: 0 | F14: 0 | G14: 0 | H14: 0 | I14: 0 | J14: 0 | K14: 0 | L14: 0 | M14: 0 | N14: 0 | O14: 0 | P14: 0 | Q14: 0 | T14: 0 | V14: =SUM(P14:T14,K14:N14) -> 0 | W14: 0 | X14: 3142.34 | Y14: 56935.17 | Z14: =IFERROR(SUM(AA14:AH14)/SUM($AA$8:$AH$8),0) -> 6.5519836e-05 | AA14: 0 | AB14: 0 | AD14: 0 | AE14: 0 | AG14: -4750 | AH14: 0 | AI14: 0 | AJ14: -19463 | AK14: -25096.9 | AL14: 0 | AM14: 0 | AN14: 0 | AO14: 0 | AP14: 0 | AQ14: 0 | AR14: 0 | AS14: 0 | AT14: 0 | AU14: 0 | AV14: 0 | AW14: -1978.83 | AX14: -1576198.5 | AY14: 0 | AZ14: 0 | BA14: 0 | BB14: 0 | BC14: 0 | BD14: -3142.34 | BF14: =V14+Y14+W14+X14 -> 60077.51 | BG14: =+SUM(AA14:BD14) -> -1630629.6 | BH14: =SUM(BF14:BG14) -> -1570552.1 | BI14: =BH14+BI13 -> -7014903.4 | BJ14: =+BI14-$AX$8 -> 11295.14 | BK14: 2018 | BL14: =SUMIFS($BF$10:$BF$208,$C$10:$C$208,">="&DATE(BK14,1,1),$C$10:$C$208,"<="&DATE(BK14,12,31)) -> 22640314 | BM14: =SUMIFS($BG$10:$BG$208,$C$10:$C$208,">="&DATE(BK14,1,1),$C$10:$C$208,"<="&DATE(BK14,12,31)) -> #REF! | BN14: =SUM(BL14:BM14) -> #REF! | BO14: =BN14+BO13 -> #REF! | BQ14: 0 | BR14: 0 | BS14: 0 | BT14: 0 | BU14: 0 | BW14: =SUM(BQ14:BT14) -> 0 | BX14: 0 | BY14: =BF14 -> 60077.51 | BZ14: =BG14 -> -1630629.6 | CA14: =BH14 -> -1570552.1 | CB14: =BI14 -> -7014903.4 | CE14: =PV($CE$5,A14,,-BH14) -> -1570552.1 | CF14: =PV($CE$5,A14,,-CA14) -> -1570552.1
A15: 0 | C15: 41821 | D15: 0 | E15: 0 | F15: 0 | G15: 0 | H15: 0 | I15: 0 | J15: 0 | K15: 0 | L15: 0 | M15: 0 | N15: 0 | O15: 0 | P15: 0 | Q15: 0 | T15: 0 | V15: =SUM(P15:T15,K15:N15) -> 0 | W15: 0 | X15: 3568.76 | Y15: 235374.71 | Z15: =IFERROR(SUM(AA15:AH15)/SUM($AA$8:$AH$8),0) -> 0.00069883126 | AA15: 0 | AB15: 9.094947e-13 | AD15: 0 | AE15: 0 | AG15: -44043.55 | AH15: -6619.71 | AI15: 0 | AJ15: -5433.1 | AK15: -69333.75 | AL15: 0 | AM15: 0 | AN15: 0 | AO15: 0 | AP15: -36373 | AQ15: 0 | AR15: 0 | AS15: 0 | AT15: -79.68 | AU15: 0 | AV15: 0 | AW15: -3592.24 | AX15: 0 | AY15: 0 | AZ15: 0 | BA15: 0 | BB15: 0 | BC15: 0 | BD15: -40372.48 | BF15: =V15+Y15+W15+X15 -> 238943.47 | BG15: =+SUM(AA15:BD15) -> -205847.51 | BH15: =SUM(BF15:BG15) -> 33095.96 | BI15: =BH15+BI14 -> -6981807.4 | BJ15: =+BI15-$AX$8 -> 44391.1 | BK15: =BK14+1 -> 2019 | BL15: =SUMIFS($BF$10:$BF$208,$C$10:$C$208,">="&DATE(BK15,1,1),$C$10:$C$208,"<="&DATE(BK15,12,31)) -> 39597442 | BM15: =SUMIFS($BG$10:$BG$208,$C$10:$C$208,">="&DATE(BK15,1,1),$C$10:$C$208,"<="&DATE(BK15,12,31)) -> #REF! | BN15: =SUM(BL15:BM15) -> #REF! | BO15: =BN15+BO14 -> #REF! | BQ15: 0 | BR15: 0 | BS15: 0 | BT15: 0 | BU15: 0 | BW15: =SUM(BQ15:BT15) -> 0 | BX15: 0 | BY15: =BF15 -> 238943.47 | BZ15: =BG15 -> -205847.51 | CA15: =BH15 -> 33095.96 | CB15: =BI15 -> -6981807.4 | CE15: =PV($CE$5,A15,,-BH15) -> 33095.96 | CF15: =PV($CE$5,A15,,-CA15) -> 33095.96
A16: 0 | C16: 41852 | D16: 0 | E16: 0 | F16: 0 | G16: 0 | H16: 0 | I16: 0 | J16: 0 | K16: 0 | L16: 0 | M16: 0 | N16: 0 | O16: 0 | P16: 0 | Q16: 0 | T16: 0 | V16: =SUM(P16:T16,K16:N16) -> 0 | W16: 0 | X16: 0 | Y16: 281736.14 | Z16: =IFERROR(SUM(AA16:AH16)/SUM($AA$8:$AH$8),0) -> 0.00076911542 | AA16: 0 | AB16: 0 | AD16: 0 | AE16: 0 | AG16: -55758.66 | AH16: 0 | AI16: 0 | AJ16: -10637.93 | AK16: -57446.09 | AL16: 0 | AM16: 0 | AN16: 0 | AO16: 0 | AP16: -194500 | AQ16: 0 | AR16: 0 | AS16: 0 | AT16: 0 | AU16: 0 | AV16: 0 | AW16: -2518.77 | AX16: 0 | AY16: 0 | AZ16: 0 | BA16: 0 | BB16: 0 | BC16: 0 | BD16: 0 | BF16: =V16+Y16+W16+X16 -> 281736.14 | BG16: =+SUM(AA16:BD16) -> -320861.45 | BH16: =SUM(BF16:BG16) -> -39125.31 | BI16: =BH16+BI15 -> -7020932.8 | BJ16: =+BI16-$AX$8 -> 5265.79 | BK16: =BK15+1 -> 2020 | BL16: =SUMIFS($BF$10:$BF$208,$C$10:$C$208,">="&DATE(BK16,1,1),$C$10:$C$208,"<="&DATE(BK16,12,31)) -> 46601516 | BM16: =SUMIFS($BG$10:$BG$208,$C$10:$C$208,">="&DATE(BK16,1,1),$C$10:$C$208,"<="&DATE(BK16,12,31)) -> #REF! | BN16: =SUM(BL16:BM16) -> #REF! | BO16: =BN16+BO15 -> #REF! | BQ16: 0 | BR16: 0 | BS16: 0 | BT16: 0 | BU16: 0 | BW16: =SUM(BQ16:BT16) -> 0 | BX16: 0 | BY16: =BF16 -> 281736.14 | BZ16: =BG16 -> -320861.45 | CA16: =BH16 -> -39125.31 | CB16: =BI16 -> -7020932.8 | CE16: =PV($CE$5,A16,,-BH16) -> -39125.31 | CF16: =PV($CE$5,A16,,-CA16) -> -39125.31
A17: 0 | C17: 41883 | D17: 0 | E17: 0 | F17: 0 | G17: 0 | H17: 0 | I17: 0 | J17: 0 | K17: 0 | L17: 0 | M17: 0 | N17: 0 | O17: 0 | P17: 0 | Q17: 0 | T17: 0 | V17: =SUM(P17:T17,K17:N17) -> 0 | W17: 0 | X17: 0 | Y17: 294606.73 | Z17: =IFERROR(SUM(AA17:AH17)/SUM($AA$8:$AH$8),0) -> 0.00082523723 | AA17: 0 | AB17: 0 | AD17: 0 | AE17: 0 | AG17: -59827.33 | AH17: 0 | AI17: 0 | AJ17: -15750 | AK17: -100881.25 | AL17: 0 | AM17: 0 | AN17: 0 | AO17: 0 | AP17: -71899.19 | AQ17: -2966 | AR17: 0 | AS17: 0 | AT17: -438.24 | AU17: 0 | AV17: 0 | AW17: -1547.75 | AX17: 0 | AY17: -683 | AZ17: 0 | BA17: 0 | BB17: 0 | BC17: 0 | BD17: 0 | BF17: =V17+Y17+W17+X17 -> 294606.73 | BG17: =+SUM(AA17:BD17) -> -253992.76 | BH17: =SUM(BF17:BG17) -> 40613.97 | BI17: =BH17+BI16 -> -6980318.8 | BJ17: =+BI17-$AX$8 -> 45879.76 | BK17: =BK16+1 -> 2021 | BL17: =SUMIFS($BF$10:$BF$208,$C$10:$C$208,">="&DATE(BK17,1,1),$C$10:$C$208,"<="&DATE(BK17,12,31)) -> 47152874 | BM17: =SUMIFS($BG$10:$BG$208,$C$10:$C$208,">="&DATE(BK17,1,1),$C$10:$C$208,"<="&DATE(BK17,12,31)) -> #REF! | BN17: =SUM(BL17:BM17) -> #REF! | BO17: =BN17+BO16 -> #REF! | BQ17: 0 | BR17: 0 | BS17: 0 | BT17: 0 | BU17: 0 | BW17: =SUM(BQ17:BT17) -> 0 | BX17: 0 | BY17: =BF17 -> 294606.73 | BZ17: =BG17 -> -253992.76 | CA17: =BH17 -> 40613.97 | CB17: =BI17 -> -6980318.8 | CE17: =PV($CE$5,A17,,-BH17) -> 40613.97 | CF17: =PV($CE$5,A17,,-CA17) -> 40613.97
A18: 0 | C18: 41913 | D18: 0 | E18: 0 | F18: 0 | G18: 0 | H18: 0 | I18: 0 | J18: 0 | K18: 0 | L18: 0 | M18: 0 | N18: 0 | O18: 0 | P18: 0 | Q18: 0 | T18: 0 | V18: =SUM(P18:T18,K18:N18) -> 0 | W18: 0 | X18: 41112.59 | Y18: 336906.22 | Z18: =IFERROR(SUM(AA18:AH18)/SUM($AA$8:$AH$8),0) -> 0.0037541002 | AA18: 0 | AB18: 0 | AD18: 0 | AE18: 0 | AG18: -51859.52 | AH18: -220301.97 | AI18: 0 | AJ18: 0 | AK18: -27325.44 | AL18: 0 | AM18: 0 | AN18: 0 | AO18: 0 | AP18: -63850 | AQ18: -2653.45 | AR18: 0 | AS18: 0 | AT18: 0 | AU18: 0 | AV18: 0 | AW18: -1170.19 | AX18: 0 | AY18: 0 | AZ18: 0 | BA18: 0 | BB18: 0 | BC18: 0 | BD18: 0 | BF18: =V18+Y18+W18+X18 -> 378018.81 | BG18: =+SUM(AA18:BD18) -> -367160.57 | BH18: =SUM(BF18:BG18) -> 10858.24 | BI18: =BH18+BI17 -> -6969460.5 | BJ18: =+BI18-$AX$8 -> 56738 | BK18: =BK17+1 -> 2022 | BL18: =SUMIFS($BF$10:$BF$208,$C$10:$C$208,">="&DATE(BK18,1,1),$C$10:$C$208,"<="&DATE(BK18,12,31)) -> 46217630 | BM18: =SUMIFS($BG$10:$BG$208,$C$10:$C$208,">="&DATE(BK18,1,1),$C$10:$C$208,"<="&DATE(BK18,12,31)) -> #REF! | BN18: =SUM(BL18:BM18) -> #REF! | BO18: =BN18+BO17 -> #REF! | BQ18: 0 | BR18: 0 | BS18: 0 | BT18: 0 | BU18: 0 | BW18: =SUM(BQ18:BT18) -> 0 | BX18: 0 | BY18: =BF18 -> 378018.81 | BZ18: =BG18 -> -367160.57 | CA18: =BH18 -> 10858.24 | CB18: =BI18 -> -6969460.5 | CE18: =PV($CE$5,A18,,-BH18) -> 10858.24 | CF18: =PV($CE$5,A18,,-CA18) -> 10858.24
A19: 0 | C19: 41944 | D19: 0 | E19: 0 | F19: 0 | G19: 0 | H19: 0 | I19: 0 | J19: 0 | K19: 0 | L19: 0 | M19: 0 | N19: 0 | O19: 0 | P19: 0 | Q19: 0 | T19: 0 | V19: =SUM(P19:T19,K19:N19) -> 0 | W19: 0 | X19: 0 | Y19: 334185.6 | Z19: =IFERROR(SUM(AA19:AH19)/SUM($AA$8:$AH$8),0) -> 0.003555496 | AA19: 0 | AB19: 0 | AD19: 0 | AE19: 0 | AG19: -37590.5 | AH19: -220172.75 | AI19: 0 | AJ19: -6000 | AK19: -19423.36 | AL19: 0 | AM19: 0 | AN19: 0 | AO19: 0 | AP19: -44398 | AQ19: -1000 | AR19: 0 | AS19: 0 | AT19: -2067.43 | AU19: 0 | AV19: 0 | AW19: -856.52 | AX19: 0 | AY19: 0 | AZ19: 0 | BA19: 0 | BB19: 0 | BC19: 0 | BD19: -30000 | BF19: =V19+Y19+W19+X19 -> 334185.6 | BG19: =+SUM(AA19:BD19) -> -361508.56 | BH19: =SUM(BF19:BG19) -> -27322.96 | BI19: =BH19+BI18 -> -6996783.5 | BJ19: =+BI19-$AX$8 -> 29415.04 | BK19: =BK18+1 -> 2023 | BL19: =SUMIFS($BF$10:$BF$208,$C$10:$C$208,">="&DATE(BK19,1,1),$C$10:$C$208,"<="&DATE(BK19,12,31)) -> 44413686 | BM19: =SUMIFS($BG$10:$BG$208,$C$10:$C$208,">="&DATE(BK19,1,1),$C$10:$C$208,"<="&DATE(BK19,12,31)) -> #REF! | BN19: =SUM(BL19:BM19) -> #REF! | BO19: =BN19+BO18 -> #REF! | BQ19: 0 | BR19: 0 | BS19: 0 | BT19: 0 | BU19: 0 | BW19: =SUM(BQ19:BT19) -> 0 | BX19: 0 | BY19: =BF19 -> 334185.6 | BZ19: =BG19 -> -361508.56 | CA19: =BH19 -> -27322.96 | CB19: =BI19 -> -6996783.5 | CE19: =PV($CE$5,A19,,-BH19) -> -27322.96 | CF19: =PV($CE$5,A19,,-CA19) -> -27322.96
A20: 0 | B20: LANÇAMENTO | C20: 41974 | D20: 0 | E20: 41 | F20: 0 | G20: 57 | H20: 3194201.4 | I20: 0 | J20: 0 | K20: 0 | L20: 0 | M20: 0 | N20: 0 | O20: 0 | P20: 0 | Q20: 0 | T20: 0 | V20: =SUM(P20:T20,K20:N20) -> 0 | W20: 0 | X20: 30000 | Y20: 143859.64 | Z20: =IFERROR(SUM(AA20:AH20)/SUM($AA$8:$AH$8),0) -> 0.001011711 | AA20: 0 | AB20: 0 | AD20: 0 | AE20: 0 | AG20: -53346.14 | AH20: -20000 | AI20: 0 | AJ20: -10380 | AK20: -12393.67 | AL20: 0 | AM20: 0 | AN20: 0 | AO20: 0 | AP20: -31120 | AQ20: -144.8 | AR20: 0 | AS20: 0 | AT20: 0 | AU20: 0 | AV20: 0 | AW20: -755.61 | AX20: 0 | AY20: 0 | AZ20: 0 | BA20: 0 | BB20: 0 | BC20: 0 | BD20: -6834.67 | BF20: =V20+Y20+W20+X20 -> 173859.64 | BG20: =+SUM(AA20:BD20) -> -134974.89 | BH20: =SUM(BF20:BG20) -> 38884.75 | BI20: =BH20+BI19 -> -6957898.8 | BJ20: =+BI20-$AX$8 -> 68299.79 | BK20: =BK19+1 -> 2024 | BL20: =SUMIFS($BF$10:$BF$208,$C$10:$C$208,">="&DATE(BK20,1,1),$C$10:$C$208,"<="&DATE(BK20,12,31)) -> 42316319 | BM20: =SUMIFS($BG$10:$BG$208,$C$10:$C$208,">="&DATE(BK20,1,1),$C$10:$C$208,"<="&DATE(BK20,12,31)) -> #REF! | BN20: =SUM(BL20:BM20) -> #REF! | BO20: =BN20+BO19 -> #REF! | BQ20: 0 | BR20: 0 | BS20: 0 | BT20: 0 | BU20: 0 | BW20: =SUM(BQ20:BT20) -> 0 | BX20: 0 | BY20: =BF20 -> 173859.64 | BZ20: =BG20 -> -134974.89 | CA20: =BH20 -> 38884.75 | CB20: =BI20 -> -6957898.8 | CE20: =PV($CE$5,A20,,-BH20) -> 38884.75 | CF20: =PV($CE$5,A20,,-CA20) -> 38884.75
A21: 0 | C21: 42005 | D21: 0 | E21: 54 | F21: 0 | G21: 72 | H21: 4293670.3 | I21: 0 | J21: 0 | K21: 0 | L21: 0 | M21: 0 | N21: 22762.72 | O21: 0 | P21: 0 | Q21: 0 | T21: 37.38 | V21: =SUM(P21:T21,K21:N21) -> 22800.1 | W21: 0 | X21: 0 | Y21: 106536.84 | Z21: =IFERROR(SUM(AA21:AH21)/SUM($AA$8:$AH$8),0) -> 0.00061989806 | AA21: 0 | AB21: -1275 | AD21: 0 | AE21: 0 | AG21: -42180.83 | AH21: -1485 | AI21: 0 | AJ21: -10124 | AK21: -7680.33 | AL21: 0 | AM21: 0 | AN21: 0 | AO21: 0 | AP21: -59703.96 | AQ21: -1250 | AR21: 0 | AS21: 0 | AT21: 0 | AU21: 0 | AV21: 0 | AW21: -2488.7 | AX21: 0 | AY21: 0 | AZ21: 0 | BA21: 0 | BB21: 0 | BC21: 0 | BD21: 0 | BF21: =V21+Y21+W21+X21 -> 129336.94 | BG21: =+SUM(AA21:BD21) -> -126187.82 | BH21: =SUM(BF21:BG21) -> 3149.12 | BI21: =BH21+BI20 -> -6954749.6 | BJ21: =+BI21-$AX$8 -> 71448.91 | BK21: =BK20+1 -> 2025 | BL21: =SUMIFS($BF$10:$BF$208,$C$10:$C$208,">="&DATE(BK21,1,1),$C$10:$C$208,"<="&DATE(BK21,12,31)) -> 32113099 | BM21: =SUMIFS($BG$10:$BG$208,$C$10:$C$208,">="&DATE(BK21,1,1),$C$10:$C$208,"<="&DATE(BK21,12,31)) -> #REF! | BN21: =SUM(BL21:BM21) -> #REF! | BO21: =BN21+BO20 -> #REF! | BQ21: 0 | BR21: 0 | BS21: 0 | BT21: 0 | BU21: 0 | BW21: =SUM(BQ21:BT21) -> 0 | BX21: 0 | BY21: =BF21 -> 129336.94 | BZ21: =BG21 -> -126187.82 | CA21: =BH21 -> 3149.12 | CB21: =BI21 -> -6954749.6 | CE21: =PV($CE$5,A21,,-BH21) -> 3149.12 | CF21: =PV($CE$5,A21,,-CA21) -> 3149.12
A22: 0 | C22: 42036 | D22: 0 | E22: 27 | F22: 0 | G22: 22 | H22: 1623277.5 | I22: 0 | J22: 0 | K22: 0 | L22: 0 | M22: 0 | N22: 68289.21 | O22: 0 | P22: 0 | Q22: 0 | T22: 192.54 | V22: =SUM(P22:T22,K22:N22) -> 68481.75 | W22: 0 | X22: 40000 | Y22: 171915.91 | Z22: =IFERROR(SUM(AA22:AH22)/SUM($AA$8:$AH$8),0) -> 0.00058492799 | AA22: 0 | AB22: -8277.22 | AD22: 0 | AE22: 0 | AG22: -34085 | AH22: -43.38 | AI22: 0 | AJ22: -6290 | AK22: -12559.04 | AL22: -77739.84 | AM22: 0 | AN22: 0 | AO22: -20000 | AP22: -136044.76 | AQ22: -483.6 | AR22: 0 | AS22: 0 | AT22: -13142.08 | AU22: 0 | AV22: 0 | AW22: -6153.63 | AX22: 0 | AY22: -830.84 | AZ22: 0 | BA22: 0 | BB22: 0 | BC22: 0 | BD22: 0 | BF22: =V22+Y22+W22+X22 -> 280397.66 | BG22: =+SUM(AA22:BD22) -> -315649.39 | BH22: =SUM(BF22:BG22) -> -35251.73 | BI22: =BH22+BI21 -> -6990001.4 | BJ22: =+BI22-$AX$8 -> 36197.18 | BK22: =BK21+1 -> 2026 | BL22: =SUMIFS($BF$10:$BF$208,$C$10:$C$208,">="&DATE(BK22,1,1),$C$10:$C$208,"<="&DATE(BK22,12,31)) -> 12337893 | BM22: =SUMIFS($BG$10:$BG$208,$C$10:$C$208,">="&DATE(BK22,1,1),$C$10:$C$208,"<="&DATE(BK22,12,31)) -> #REF! | BN22: =SUM(BL22:BM22) -> #REF! | BO22: =BN22+BO21 -> #REF! | BQ22: 0 | BR22: 0 | BS22: 0 | BT22: 0 | BU22: 0 | BW22: =SUM(BQ22:BT22) -> 0 | BX22: 0 | BY22: =BF22 -> 280397.66 | BZ22: =BG22 -> -315649.39 | CA22: =BH22 -> -35251.73 | CB22: =BI22 -> -6990001.4 | CE22: =PV($CE$5,A22,,-BH22) -> -35251.73 | CF22: =PV($CE$5,A22,,-CA22) -> -35251.73
A23: 0 | C23: 42064 | D23: 0 | E23: 7 | F23: 0 | G23: 9 | H23: 544488 | I23: 0 | J23: 0 | K23: 0 | L23: 0 | M23: 0 | N23: 187309.38 | O23: 0 | P23: 0 | Q23: 0 | T23: 1073.48 | V23: =SUM(P23:T23,K23:N23) -> 188382.86 | W23: 0 | X23: 0 | Y23: 361130.16 | Z23: =IFERROR(SUM(AA23:AH23)/SUM($AA$8:$AH$8),0) -> 0.00069120227 | AA23: 0 | AB23: -9603.18 | AD23: 0 | AE23: 0 | AG23: -40507 | AH23: 0 | AI23: 0 | AJ23: -6000 | AK23: -10026.14 | AL23: -147088.77 | AM23: 0 | AN23: 0 | AO23: 0 | AP23: -150712.89 | AQ23: 0 | AR23: 0 | AS23: 0 | AT23: -24511.16 | AU23: -4973.2 | AV23: 0 | AW23: -872.34 | AX23: 0 | AY23: -2492.56 | AZ23: 0 | BA23: 0 | BB23: 0 | BC23: 0 | BD23: -40000 | BF23: =V23+Y23+W23+X23 -> 549513.02 | BG23: =+SUM(AA23:BD23) -> -436787.24 | BH23: =SUM(BF23:BG23) -> 112725.78 | BI23: =BH23+BI22 -> -6877275.6 | BJ23: =+BI23-$AX$8 -> 148922.96 | BK23: =BK22+1 -> 2027 | BL23: =SUMIFS($BF$10:$BF$208,$C$10:$C$208,">="&DATE(BK23,1,1),$C$10:$C$208,"<="&DATE(BK23,12,31)) -> 3074450 | BM23: =SUMIFS($BG$10:$BG$208,$C$10:$C$208,">="&DATE(BK23,1,1),$C$10:$C$208,"<="&DATE(BK23,12,31)) -> #REF! | BN23: =SUM(BL23:BM23) -> #REF! | BO23: =BN23+BO22 -> #REF! | BQ23: 0 | BR23: 0 | BS23: 0 | BT23: 0 | BU23: 0 | BW23: =SUM(BQ23:BT23) -> 0 | BX23: 0 | BY23: =BF23 -> 549513.02 | BZ23: =BG23 -> -436787.24 | CA23: =BH23 -> 112725.78 | CB23: =BI23 -> -6877275.6 | CE23: =PV($CE$5,A23,,-BH23) -> 112725.78 | CF23: =PV($CE$5,A23,,-CA23) -> 112725.78
A24: 0 | C24: 42095 | D24: 0 | E24: 18 | F24: 0 | G24: 26 | H24: 1575588.2 | I24: 0 | J24: 0 | K24: 0 | L24: 0 | M24: 0 | N24: 237247.2 | O24: 0 | P24: 0 | Q24: 0 | T24: 1678.86 | V24: =SUM(P24:T24,K24:N24) -> 238926.06 | W24: 0 | X24: 4948.26 | Y24: 148490.04 | Z24: =IFERROR(SUM(AA24:AH24)/SUM($AA$8:$AH$8),0) -> 0.00069491593 | AA24: 0 | AB24: -3551.4 | AD24: 0 | AE24: 0 | AG24: -46828.01 | AH24: 0 | AI24: 0 | AJ24: -6000 | AK24: -7071.64 | AL24: -110158.26 | AM24: -6392.22 | AN24: 0 | AO24: -168237.34 | AP24: -118783.71 | AQ24: -4875.2 | AR24: 0 | AS24: 0 | AT24: -30265.88 | AU24: -3500.45 | AV24: 0 | AW24: -2363.12 | AX24: 0 | AY24: -9056.6 | AZ24: 0 | BA24: 0 | BB24: 0 | BC24: 0 | BD24: -4948.26 | BF24: =V24+Y24+W24+X24 -> 392364.36 | BG24: =+SUM(AA24:BD24) -> -522032.09 | BH24: =SUM(BF24:BG24) -> -129667.73 | BI24: =BH24+BI23 -> -7006943.3 | BJ24: =+BI24-$AX$8 -> 19255.23 | BK24: =BK23+1 -> 2028 | BL24: =SUMIFS($BF$10:$BF$208,$C$10:$C$208,">="&DATE(BK24,1,1),$C$10:$C$208,"<="&DATE(BK24,12,31)) -> 179206.91 | BM24: =SUMIFS($BG$10:$BG$208,$C$10:$C$208,">="&DATE(BK24,1,1),$C$10:$C$208,"<="&DATE(BK24,12,31)) -> #REF! | BN24: =SUM(BL24:BM24) -> #REF! | BO24: =BN24+BO23 -> #REF! | BQ24: 0 | BR24: 0 | BS24: 0 | BT24: 0 | BU24: 0 | BW24: =SUM(BQ24:BT24) -> 0 | BX24: 0 | BY24: =BF24 -> 392364.36 | BZ24: =BG24 -> -522032.09 | CA24: =BH24 -> -129667.73 | CB24: =BI24 -> -7006943.3 | CE24: =PV($CE$5,A24,,-BH24) -> -129667.73 | CF24: =PV($CE$5,A24,,-CA24) -> -129667.73
A25: 0 | C25: 42125 | D25: 0 | E25: 4 | F25: 0 | G25: 1 | H25: 162965.89 | I25: 0 | J25: 0 | K25: 0 | L25: 0 | M25: 0 | N25: 273491.18 | O25: 0 | P25: 0 | Q25: 0 | T25: 2569.78 | V25: =SUM(P25:T25,K25:N25) -> 276060.96 | W25: 0 | X25: 6834.67 | Y25: 296905.35 | Z25: =IFERROR(SUM(AA25:AH25)/SUM($AA$8:$AH$8),0) -> 0.002838825 | AA25: -142923.59 | AB25: -3433.07 | AD25: 0 | AE25: 0 | AG25: -59450 | AH25: 0 | AI25: 0 | AJ25: -6000 | AK25: -8716.86 | AL25: -119639.56 | AM25: -5302.3 | AN25: 0 | AO25: -103031.78 | AP25: -83691.21 | AQ25: -9587.47 | AR25: 0 | AS25: 0 | AT25: -3743 | AU25: 0 | AV25: -545.47 | AW25: -2200.23 | AX25: 0 | AY25: -10879.34 | AZ25: 0 | BA25: 0 | BB25: 0 | BC25: 0 | BD25: 0 | BF25: =V25+Y25+W25+X25 -> 579800.98 | BG25: =+SUM(AA25:BD25) -> -559143.88 | BH25: =SUM(BF25:BG25) -> 20657.1 | BI25: =BH25+BI24 -> -6986286.2 | BJ25: =+BI25-$AX$8 -> 39912.33 | BK25: =BK24+1 -> 2029 | BL25: =SUMIFS($BF$10:$BF$208,$C$10:$C$208,">="&DATE(BK25,1,1),$C$10:$C$208,"<="&DATE(BK25,12,31)) -> 0 | BM25: =SUMIFS($BG$10:$BG$208,$C$10:$C$208,">="&DATE(BK25,1,1),$C$10:$C$208,"<="&DATE(BK25,12,31)) -> #REF! | BN25: =SUM(BL25:BM25) -> #REF! | BO25: =BN25+BO24 -> #REF! | BQ25: 0 | BR25: 0 | BS25: 0 | BT25: 0 | BU25: 0 | BW25: =SUM(BQ25:BT25) -> 0 | BX25: 0 | BY25: =BF25 -> 579800.98 | BZ25: =BG25 -> -559143.88 | CA25: =BH25 -> 20657.1 | CB25: =BI25 -> -6986286.2 | CE25: =PV($CE$5,A25,,-BH25) -> 20657.1 | CF25: =PV($CE$5,A25,,-CA25) -> 20657.1
A26: 0 | C26: 42156 | D26: 0 | E26: 10 | F26: 0 | G26: 4 | H26: 466297.66 | I26: 0 | J26: 0 | K26: 0 | L26: 0 | M26: 0 | N26: 310796.87 | O26: 0 | P26: 0 | Q26: 0 | T26: 3309.05 | V26: =SUM(P26:T26,K26:N26) -> 314105.92 | W26: 0 | X26: 0 | Y26: 195692.3 | Z26: =IFERROR(SUM(AA26:AH26)/SUM($AA$8:$AH$8),0) -> 0.0025497804 | AA26: -131489.7 | AB26: -3868.73 | AD26: 0 | AE26: 0 | AG26: -49493.33 | AH26: 0 | AI26: 0 | AJ26: -6000 | AK26: -1777 | AL26: -115534.5 | AM26: -6204.77 | AN26: 0 | AO26: -75963.08 | AP26: -62940.11 | AQ26: -9662 | AR26: 0 | AS26: 0 | AT26: -29041.72 | AU26: -1271.15 | AV26: -2171 | AW26: -2883.25 | AX26: 0 | AY26: -12182.34 | AZ26: 0 | BA26: 0 | BB26: 0 | BC26: 0 | BD26: 0 | BF26: =V26+Y26+W26+X26 -> 509798.22 | BG26: =+SUM(AA26:BD26) -> -510482.68 | BH26: =SUM(BF26:BG26) -> -684.46 | BI26: =BH26+BI25 -> -6986970.7 | BJ26: =+BI26-$AX$8 -> 39227.87 | BK26: =BK25+1 -> 2030 | BL26: =SUMIFS($BF$10:$BF$208,$C$10:$C$208,">="&DATE(BK26,1,1),$C$10:$C$208,"<="&DATE(BK26,12,31)) -> 0 | BM26: =SUMIFS($BG$10:$BG$208,$C$10:$C$208,">="&DATE(BK26,1,1),$C$10:$C$208,"<="&DATE(BK26,12,31)) -> 0 | BN26: =SUM(BL26:BM26) -> 0 | BO26: =BN26+BO25 -> #REF! | BQ26: 0 | BR26: 0 | BS26: 0 | BT26: 0 | BU26: 0 | BW26: =SUM(BQ26:BT26) -> 0 | BX26: 0 | BY26: =BF26 -> 509798.22 | BZ26: =BG26 -> -510482.68 | CA26: =BH26 -> -684.46 | CB26: =BI26 -> -6986970.7 | CE26: =PV($CE$5,A26,,-BH26) -> -684.46 | CF26: =PV($CE$5,A26,,-CA26) -> -684.46
A27: 0 | C27: 42186 | D27: 0 | E27: 135 | F27: 0 | G27: 89 | H27: 8005383.5 | I27: 0 | J27: 0 | K27: 0 | L27: 0 | M27: 0 | N27: 376495.52 | O27: 0 | P27: 0 | Q27: 0 | T27: 2272.66 | V27: =SUM(P27:T27,K27:N27) -> 378768.18 | W27: 0 | X27: 364.53 | Y27: 124705.75 | Z27: =IFERROR(SUM(AA27:AH27)/SUM($AA$8:$AH$8),0) -> 0.0019854325 | AA27: -133067.57 | AB27: -5740.59 | AD27: 0 | AE27: 0 | AG27: -5130 | AH27: 0 | AI27: 0 | AJ27: -6000 | AK27: -212.55 | AL27: -113627.72 | AM27: -7061.48 | AN27: 0 | AO27: -131297.67 | AP27: -51363 | AQ27: -11296.4 | AR27: 0 | AS27: 0 | AT27: -13085 | AU27: -1971.45 | AV27: -6750.3 | AW27: -3045.47 | AX27: 0 | AY27: -18528.05 | AZ27: 0 | BA27: 0 | BB27: 0 | BC27: 0 | BD27: 0 | BF27: =V27+Y27+W27+X27 -> 503838.46 | BG27: =+SUM(AA27:BD27) -> -508177.25 | BH27: =SUM(BF27:BG27) -> -4338.79 | BI27: =BH27+BI26 -> -6991309.5 | BJ27: =+BI27-$AX$8 -> 34889.08 | BK27: =BK26+1 -> 2031 | BL27: =SUMIFS($BF$10:$BF$208,$C$10:$C$208,">="&DATE(BK27,1,1),$C$10:$C$208,"<="&DATE(BK27,12,31)) -> 0 | BM27: =SUMIFS($BG$10:$BG$208,$C$10:$C$208,">="&DATE(BK27,1,1),$C$10:$C$208,"<="&DATE(BK27,12,31)) -> 0 | BN27: =SUM(BL27:BM27) -> 0 | BO27: =BN27+BO26 -> #REF! | BQ27: 0 | BR27: 0 | BS27: 0 | BT27: 0 | BU27: 0 | BW27: =SUM(BQ27:BT27) -> 0 | BX27: 0 | BY27: =BF27 -> 503838.46 | BZ27: =BG27 -> -508177.25 | CA27: =BH27 -> -4338.79 | CB27: =BI27 -> -6991309.5 | CE27: =PV($CE$5,A27,,-BH27) -> -4338.79 | CF27: =PV($CE$5,A27,,-CA27) -> -4338.79
