Workbook

Sheet ANALISE GERAL
B1: GRUPO ESQUADRA ADMINISTRACAO & ASSESSORIA EMPRESARIAL LTDA
B2: DIAF - FATURAMENTO
B3: APURAÇÃO DE FATURAMENTO - POR COMPETÊNCIA
C7: OBJETO - ESTADO | F7: JANEIRO | G7: FEVEREIRO | H7: MARÇO | I7: ABRIL | J7: MAIO | K7: JUNHO | L7: JULHO | M7: TOTAL
C8: PATRIMONIAL | F8: ='FATURAMENTO GERAL 2018'!I48 -> 1201868.6 | G8: ='FATURAMENTO GERAL 2018'!J48 -> 541254.33 | H8: ='FATURAMENTO GERAL 2018'!K48 -> 508347.95 | I8: ='FATURAMENTO GERAL 2018'!L48 -> 1024287.3 | J8: ='FATURAMENTO GERAL 2018'!M48 -> 1091517.8 | K8: ='FATURAMENTO GERAL 2018'!N48 -> 1395528 | L8: ='FATURAMENTO GERAL 2018'!O48 -> 1385682.4 | M8: =SUM(F8:H8) -> 2251470.9
C9: TOTAL | F9: =SUM(F8:F8) -> 1201868.6 | G9: =SUM(G8:G8) -> 541254.33 | H9: =SUM(H8:H8) -> 508347.95 | I9: =SUM(I8:I8) -> 1024287.3 | J9: =SUM(J8:J8) -> 1091517.8 | K9: =SUM(K8:K8) -> 1395528 | L9: =SUM(L8:L8) -> 1385682.4 | M9: =SUM(F9:H9) -> 2251470.9
C11: MINAS GERAIS | F11: ='FATURAMENTO GERAL 2018'!I57 -> 412300.8 | G11: ='FATURAMENTO GERAL 2018'!J57 -> 421577.46 | H11: ='FATURAMENTO GERAL 2018'!K57 -> 388671.08 | I11: ='FATURAMENTO GERAL 2018'!L57 -> 452038.91 | J11: ='FATURAMENTO GERAL 2018'!M57 -> 465815.55 | K11: ='FATURAMENTO GERAL 2018'!N57 -> 424228.55 | L11: ='FATURAMENTO GERAL 2018'!O57 -> 455966.17 | M11: =SUM(F11:H11) -> 1222549.3
C12: UBERLÂNDIA | F12: ='FATURAMENTO GERAL 2018'!I58 -> 0 | G12: ='FATURAMENTO GERAL 2018'!J58 -> 0 | H12: ='FATURAMENTO GERAL 2018'!K58 -> 0 | I12: ='FATURAMENTO GERAL 2018'!L58 -> 0 | J12: ='FATURAMENTO GERAL 2018'!M58 -> 0 | K12: ='FATURAMENTO GERAL 2018'!N58 -> 0 | L12: ='FATURAMENTO GERAL 2018'!O58 -> 0 | M12: =SUM(F12:H12) -> 0
C13: SÃO PAULO | F13: ='FATURAMENTO GERAL 2018'!I59 -> 784478.24 | G13: ='FATURAMENTO GERAL 2018'!J59 -> 115859.67 | H13: ='FATURAMENTO GERAL 2018'!K59 -> 115859.67 | I13: ='FATURAMENTO GERAL 2018'!L59 -> 568431.23 | J13: ='FATURAMENTO GERAL 2018'!M59 -> 569996.72 | K13: ='FATURAMENTO GERAL 2018'!N59 -> 772457.53 | L13: ='FATURAMENTO GERAL 2018'!O59 -> 783492.53 | M13: =SUM(F13:H13) -> 1016197.6
C14: ESPIRITO SANTO | F14: ='FATURAMENTO GERAL 2018'!I60 -> 5089.6 | G14: ='FATURAMENTO GERAL 2018'!J60 -> 3817.2 | H14: ='FATURAMENTO GERAL 2018'!K60 -> 3817.2 | I14: ='FATURAMENTO GERAL 2018'!L60 -> 3817.2 | J14: ='FATURAMENTO GERAL 2018'!M60 -> 3817.2 | K14: ='FATURAMENTO GERAL 2018'!N60 -> 3817.2 | L14: ='FATURAMENTO GERAL 2018'!O60 -> 3817.2 | M14: =SUM(F14:H14) -> 12724
C15: TOTAL | F15: =SUM(F11:F14) -> 1201868.6 | G15: =SUM(G11:G14) -> 541254.33 | H15: =SUM(H11:H14) -> 508347.95 | I15: =SUM(I11:I14) -> 1024287.3 | J15: =SUM(J11:J14) -> 1039629.5 | K15: =SUM(K11:K14) -> 1200503.3 | L15: =SUM(L11:L14) -> 1243275.9 | M15: =SUM(F15:H15) -> 2251470.9

Sheet FATURAMENTO GERAL 2018
A1: GRUPO ESQUADRA ADMINISTRACAO & ASSESSORIA EMPRESARIAL LTDA
A2: DIAF - FATURAMENTO
A3: APURAÇÃO DE FATURAMENTO - POR COMPETÊNCIA
B7: ITEM | C7: CLIENTE | D7: TIPO CONTRATO | E7: FORMA DE PAGAMENTO | F7: OBJETO | G7: FILIAL | H7: OBJETO - ESTADO | I7: JANEIRO | J7: FEVEREIRO | K7: MARÇO | L7: ABRIL | M7: MAIO | N7: JUNHO | O7: JULHO | P7: AGOSTO | Q7: SETEMBRO | R7: OUTUBRO | S7: NOVEMBRO | T7: DEZEMBRO | U7: TOTAL
B8: 1 | C8: APERAM INOX AMERICA DO SUL S.A | D8: PRIVADO | E8: CREDITO EM CONTA | F8: BRIGADISTA | G8: MG | H8: =CONCATENATE(F8," ",G8) -> BRIGADISTA MG | L8: 45308.82 | M8: 48694.95 | N8: 48867.02 | O8: 48867.02 | P8: 48867.02 | Q8: 48867.02 | R8: 63969.96 | S8: 73727.13 | T8: 95505.15 | U8: =SUM(I8:T8) -> 522674.09
B9: =B8+1 -> 2 | C9: CBRE - CONDOMINIO EDIFICIO AURELIANO CHAVES | D9: PRIVADO | E9: BOLETO | F9: PORTARIA | G9: MG | H9: =CONCATENATE(F9," ",G9) -> PORTARIA MG | I9: 59319.43 | J9: 59319.43 | K9: 59319.43 | L9: 59319.43 | M9: 66429.98 | N9: 62681.93 | O9: 63338.25 | P9: 59515 | Q9: 59515 | R9: 59515 | S9: 59515 | T9: 59410.82 | U9: =SUM(I9:T9) -> 727198.7
B10: =B9+1 -> 3 | C10: MIX TUDO COMERCIO E SERVIÇOS EIRELLI - COLIBRI FESTAS | D10: PRIVADO | E10: BOLETO | F10: PORTARIA | G10: ES | H10: =CONCATENATE(F10," ",G10) -> PORTARIA ES | I10: 5089.6 | J10: 3817.2 | K10: 3817.2 | L10: 3817.2 | M10: 3817.2 | N10: 3817.2 | O10: 3817.2 | P10: 3817.2 | Q10: 3817.2 | R10: 3817.2 | S10: 3817.2 | T10: 3817.2 | U10: =SUM(I10:T10) -> 47078.8
B11: =B10+1 -> 4 | C11: CONDOMINIO DO CENTRO COMERCIAL PORTAL NOVA LIMA | D11: PRIVADO | E11: BOLETO | F11: PORTARIA | G11: MG | H11: =CONCATENATE(F11," ",G11) -> PORTARIA MG | O11: 6433.83 | P11: 8773.41 | Q11: 16607.25 | R11: 16607.25 | S11: 16607.25 | T11: 16607.25 | U11: =SUM(I11:T11) -> 81636.24
B12: =B11+1 -> 5 | C12: CONDOMINIO EDIFICIO CITTA GIARDINO | D12: PRIVADO | E12: BOLETO | F12: PORTARIA | G12: MG | H12: =CONCATENATE(F12," ",G12) -> PORTARIA MG | I12: 31080.24 | J12: 31080.24 | K12: 31080.24 | L12: 31080.24 | M12: 31080.24 | N12: 31080.24 | O12: 31080.24 | P12: 38539.49 | Q12: 32012.64 | R12: 32012.64 | S12: 32012.64 | T12: 32012.64 | U12: =SUM(I12:T12) -> 384151.73
B13: =B12+1 -> 6 | C13: CONDOMINIO EMPRESARIAL SERRA SUL | D13: PRIVADO | E13: BOLETO | F13: PORTARIA | G13: MG | H13: =CONCATENATE(F13," ",G13) -> PORTARIA MG | I13: 40139.39 | J13: 40139.39 | K13: 40139.39 | L13: 32460.4 | M13: 34030.99 | N13: 33287.03 | O13: 33287.03 | P13: 33287.03 | Q13: 33287.03 | R13: 47222.4 | S13: 34539.97 | T13: 47301.53 | U13: =SUM(I13:T13) -> 449121.58
B14: =B13+1 -> 7 | C14: CONDOMINIO MINASCASA O SHOPPING DO LAR | D14: PRIVADO | E14: BOLETO | F14: PORTARIA | G14: MG | H14: =CONCATENATE(F14," ",G14) -> PORTARIA MG | I14: 34714.22 | J14: 34714.22 | K14: 34714.22 | L14: 41093.61 | M14: 36309.07 | N14: 36309.07 | O14: 36309.07 | P14: 36309.07 | Q14: 36309.07 | R14: 36309.07 | S14: 36309.07 | T14: 36309.07 | U14: =SUM(I14:T14) -> 435708.83
B15: =B14+1 -> 8 | C15: CRUZEIRO ESPORTE CLUBE | D15: PRIVADO | E15: BOLETO | F15: PORTARIA | G15: MG | H15: =CONCATENATE(F15," ",G15) -> PORTARIA MG | O15: 15341.25 | U15: =SUM(I15:T15) -> 15341.25
B16: =B15+1 -> 9 | C16: DUFRY LOJAS FRANCAS LTDA | D16: PRIVADO | E16: CREDITO EM CONTA | F16: PORTARIA | G16: MG | H16: =CONCATENATE(F16," ",G16) -> PORTARIA MG | I16: 13100.69 | J16: 12880.95 | K16: 12880.95 | L16: 13017.81 | M16: 14463.83 | N16: 13133.66 | O16: 13133.66 | P16: 6692.38 | Q16: 6764.61 | R16: 3346.19 | S16: 3731.3 | T16: 3346.19 | U16: =SUM(I16:T16) -> 116492.22
B17: =B16+1 -> 10 | C17: EMPRESA DE TRANSPORTES ATLAS LTDA | D17: PRIVADO | E17: BOLETO | F17: PORTARIA | G17: MG | H17: =CONCATENATE(F17," ",G17) -> PORTARIA MG | I17: 3019.39 | U17: =SUM(I17:T17) -> 3019.39
B18: =B17+1 -> 11 | C18: FEDEX BRASIL LOGISTICA E TRANSPORTE LTDA | D18: PRIVADO | E18: BOLETO | F18: PORTARIA | G18: MG | H18: =CONCATENATE(F18," ",G18) -> PORTARIA MG | I18: 7122.86 | J18: 7122.86 | K18: 7122.86 | L18: 7122.86 | M18: 7122.86 | N18: 7122.86 | O18: 7122.86 | U18: =SUM(I18:T18) -> 49860.02
B19: =B18+1 -> 12 | C19: FEMSA - ATLAS E EXPRESSO JUNDIAI | D19: PRIVADO | E19: BOLETO | F19: PORTARIA | G19: SP | H19: =CONCATENATE(F19," ",G19) -> PORTARIA SP | I19: 234520.02 | U19: =SUM(I19:T19) -> 234520.02
B20: =B19+1 -> 13 | C20: FUNDACAO FIAT SAUDE E BEM ESTAR | D20: PRIVADO | E20: BOLETO | F20: PORTARIA | G20: MG | H20: =CONCATENATE(F20," ",G20) -> PORTARIA MG | I20: 6296.62 | U20: =SUM(I20:T20) -> 6296.62
B21: =B20+1 -> 14 | C21: GPA - COMPANHIA BRASILEIRA DE DISTRIBUICAO | D21: PRIVADO | E21: CREDITO EM CONTA | F21: PORTARIA | G21: RJ | H21: =CONCATENATE(F21," ",G21) -> PORTARIA RJ | P21: 29820.84 | Q21: 217145.09 | R21: 197331.26 | S21: 187145.7 | T21: 185145.7 | U21: =SUM(I21:T21) -> 816588.59
B22: =B21+1 -> 15 | C22: GROWN OPTICAL LTDA | D22: PRIVADO | E22: CREDITO EM CONTA | F22: PORTARIA | G22: SP | H22: =CONCATENATE(F22," ",G22) -> PORTARIA SP | I22: 45300.46 | J22: 45300.46 | K22: 45300.46 | L22: 45300.46 | M22: 45300.46 | N22: 45300.46 | O22: 45300.46 | P22: 45300.46 | Q22: 45300.46 | R22: 45300.46 | S22: 45300.46 | T22: 51561.87 | U22: =SUM(I22:T22) -> 549866.93
B23: =B22+1 -> 16 | C23: INDUSTRIA & COMERCIO DE EXPLOSIVOS NITROSUL LTDA - ME | D23: PRIVADO | E23: BOLETO | F23: PORTARIA | G23: MG | H23: =CONCATENATE(F23," ",G23) -> PORTARIA MG | I23: 14796.27 | J23: 14215 | K23: 14215 | L23: 14215 | M23: 14215 | N23: 14215 | O23: 14215 | P23: 14215 | Q23: 14215 | R23: 14215 | S23: 14215 | T23: 14215 | U23: =SUM(I23:T23) -> 171161.27
B24: =B23+1 -> 17 | C24: JHSF - AVEIRO INCORPORACOES LTDA/SHOPPING CIDADE JARDIM | D24: PRIVADO | E24: BOLETO | F24: PORTARIA | G24: SP | H24: =CONCATENATE(F24," ",G24) -> PORTARIA SP | I24: 15665.76 | J24: 15665.76 | K24: 15665.76 | L24: 15665.76 | M24: 15665.76 | N24: 15665.76 | O24: 15665.76 | P24: 15665.76 | Q24: 15665.76 | R24: 7310.69 | U24: =SUM(I24:T24) -> 148302.53
B25: =B24+1 -> 18 | C25: JHSF - CAPRI ADMINISTRADORA DE BENS LTDA | D25: PRIVADO | E25: BOLETO | F25: PORTARIA | G25: SP | H25: =CONCATENATE(F25," ",G25) -> PORTARIA SP | I25: 3995.39 | J25: 3995.39 | K25: 3995.39 | L25: 3995.39 | M25: 3995.39 | N25: 3995.39 | O25: 3995.39 | P25: 3995.39 | Q25: 3995.39 | R25: 3995.39 | S25: 3995.39 | T25: 3995.39 | U25: =SUM(I25:T25) -> 47944.68
B26: =B25+1 -> 19 | C26: LUFT TRANSPORTS RODOVIARIOS E ARMAZENS GERAIS LTDA | D26: PRIVADO | E26: BOLETO | F26: PORTARIA | G26: MG | H26: =CONCATENATE(F26," ",G26) -> PORTARIA MG | I26: 14547.64 | J26: 14547.64 | K26: 484.92 | U26: =SUM(I26:T26) -> 29580.2
B27: =B26+1 -> 20 | C27: MAGAZINE LUIZA | D27: PRIVADO | E27: CREDITO EM CONTA | F27: PORTARIA | G27: SP | H27: =CONCATENATE(F27," ",G27) -> PORTARIA SP | I27: 50897.8 | J27: 50898.06 | K27: 50898.06 | L27: 50897.8 | M27: 52142 | N27: 52354.97 | O27: 55694.72 | P27: 52354.97 | Q27: 52354.97 | R27: 52354.97 | S27: 52354.97 | T27: 60078.05 | U27: =SUM(I27:T27) -> 633281.34
B28: =B27+1 -> 21 | C28: MATE COURO S A | D28: PRIVADO | E28: BOLETO | F28: PORTARIA | G28: MG | H28: =CONCATENATE(F28," ",G28) -> PORTARIA MG | I28: 8032.97 | J28: 8032.97 | K28: 8032.97 | L28: 8032.97 | M28: 8032.97 | N28: 8032.97 | O28: 8032.97 | P28: 10927.72 | Q28: 8394.81 | R28: 8394.81 | S28: 8394.81 | T28: 8394.81 | U28: =SUM(I28:T28) -> 100737.75
B29: =B28+1 -> 22 | C29: MINAS ARENA | D29: PRIVADO | E29: CREDITO EM CONTA | F29: PORTARIA | G29: MG | H29: =CONCATENATE(F29," ",G29) -> PORTARIA MG | I29: 15080.15 | J29: 34473.83 | K29: 15630.17 | L29: 26853.52 | M29: 34441.59 | N29: 13809.57 | O29: 23979.54 | P29: 32646.62 | Q29: 32284.13 | R29: 32501.91 | S29: 25561.53 | T29: 0 | U29: =SUM(I29:T29) -> 287262.56
B30: =B29+1 -> 23 | C30: MRS LOGISTICA S.A | D30: PRIVADO | E30: CREDITO EM CONTA | F30: PORTARIA | G30: MG | H30: =CONCATENATE(F30," ",G30) -> PORTARIA MG | Q30: 325435.51 | R30: 327560.95 | S30: 346689.91 | T30: 333317.35 | U30: =SUM(I30:T30) -> 1333003.7
B31: =B30+1 -> 24 | C31: MINAS TEXTEIS LTDA - AUTONEUM BRASIL | D31: PRIVADO | E31: BOLETO | F31: PORTARIA | G31: MG | H31: =CONCATENATE(F31," ",G31) -> PORTARIA MG | I31: 20748.38 | J31: 20748.38 | K31: 20748.38 | L31: 24036.38 | M31: 23860.63 | N31: 21370.83 | O31: 21783.25 | P31: 21370.83 | Q31: 25845.37 | R31: 22929.93 | S31: 22929.93 | T31: 22929.93 | U31: =SUM(I31:T31) -> 269302.22
B32: =B31+1 -> 25 | C32: NATURA | D32: PRIVADO | E32: CREDITO EM CONTA | F32: MOTOLINK | G32: RJ | H32: =CONCATENATE(F32," ",G32) -> MOTOLINK RJ | M32: =45916.68+5971.68 -> 51888.36 | N32: =117872.1+77152.67 -> 195024.77 | O32: 142406.5 | P32: 153703.98 | Q32: 140020.68 | R32: 140010.33 | S32: 92083 | T32: 8384 | U32: =SUM(I32:T32) -> 923521.62
B33: =B32+1 -> 26 | C33: NATURA | D33: PRIVADO | E33: CREDITO EM CONTA | F33: MOTOLINK | G33: SP | H33: =CONCATENATE(F33," ",G33) -> MOTOLINK SP | N33: =192432+8887.1 -> 201319.1 | O33: 214070.84 | P33: 233328.57 | Q33: 199978.63 | R33: 141350 | S33: 72921 | T33: 2821 | U33: =SUM(I33:T33) -> 1065789.1
B34: =B33+1 -> 27 | C34: PROCOMP INDUSTRIA ELETRÔNICA | D34: PRIVADO | E34: BOLETO | F34: PORTARIA | G34: MG | H34: =CONCATENATE(F34," ",G34) -> PORTARIA MG | I34: 14889.15 | J34: 14889.15 | K34: 14889.15 | L34: 14889.15 | M34: 14889.15 | N34: 14889.15 | O34: 14889.15 | P34: 14889.15 | Q34: 14889.15 | R34: 14889.15 | S34: 14889.15 | T34: 14889.15 | U34: =SUM(I34:T34) -> 178669.8
B35: =B34+1 -> 28 | C35: PUR EQUIPAMENTOS INDUSTRIAIS KTDA | D35: PRIVADO | E35: BOLETO | F35: PORTARIA | G35: MG | H35: =CONCATENATE(F35," ",G35) -> PORTARIA MG | I35: 5060.18 | J35: 5060.18 | K35: 5060.18 | L35: 5060.18 | M35: 5819.2 | N35: 5211.98 | O35: 5211.98 | P35: 5211.98 | Q35: 5211.98 | R35: 5211.98 | S35: 5211.98 | T35: 5211.98 | U35: =SUM(I35:T35) -> 62543.78
B36: =B35+1 -> 29 | C36: SICOOB NOSSACOOP - Barbacena | D36: PRIVADO | E36: BOLETO | F36: PORTARIA | G36: MG | H36: =CONCATENATE(F36," ",G36) -> PORTARIA MG | Q36: 5075.66 | R36: 3713.9 | S36: 3713.9 | T36: 3713.9 | U36: =SUM(I36:T36) -> 16217.36
B37: =B36+1 -> 30 | C37: SICOOB NOSSACOOP - Ibirite | D37: PRIVADO | E37: BOLETO | F37: PORTARIA | G37: MG | H37: =CONCATENATE(F37," ",G37) -> PORTARIA MG | O37: 4951.87 | P37: 3713.9 | Q37: 3713.9 | R37: 3713.9 | S37: 3713.9 | T37: 3713.9 | U37: =SUM(I37:T37) -> 23521.37
B38: =B37+1 -> 31 | C38: SICOOB NOSSACOOP - Mariana | D38: PRIVADO | E38: BOLETO | F38: PORTARIA | G38: MG | H38: =CONCATENATE(F38," ",G38) -> PORTARIA MG | O38: 4951.87 | P38: 3713.9 | Q38: 3713.9 | R38: 3713.9 | S38: 3713.9 | T38: 3713.9 | U38: =SUM(I38:T38) -> 23521.37
B39: =B38+1 -> 32 | C39: SICOOB NOSSACOOP - Olegario Maciel | D39: PRIVADO | E39: BOLETO | F39: PORTARIA | G39: MG | H39: =CONCATENATE(F39," ",G39) -> PORTARIA MG | O39: 3218.71 | P39: 3713.9 | Q39: 3713.9 | R39: 3713.9 | S39: 3713.9 | T39: 3713.9 | U39: =SUM(I39:T39) -> 21788.21
B40: =B39+1 -> 33 | C40: SICOOB NOSSACOOP - São Joao del rei | D40: PRIVADO | E40: BOLETO | F40: PORTARIA | G40: MG | H40: =CONCATENATE(F40," ",G40) -> PORTARIA MG | Q40: 4951.87 | R40: 3713.9 | S40: 3713.9 | T40: 3713.9 | U40: =SUM(I40:T40) -> 16093.57
B41: =B40+1 -> 34 | C41: SICOOB NOSSACOOP - São José da Lapa | D41: PRIVADO | E41: BOLETO | F41: PORTARIA | G41: MG | H41: =CONCATENATE(F41," ",G41) -> PORTARIA MG | O41: 7056.41 | P41: 3713.9 | Q41: 3713.9 | R41: 3713.9 | S41: 3713.9 | T41: 3713.9 | U41: =SUM(I41:T41) -> 25625.91
B42: =B41+1 -> 35 | C42: SPE INOVA BH S/A | D42: PRIVADO | E42: BOLETO | F42: PORTARIA | G42: MG | H42: =CONCATENATE(F42," ",G42) -> PORTARIA MG | I42: 17526.05 | J42: 17526.05 | K42: 17526.05 | L42: 19629.16 | M42: 18051.82 | N42: 18051.82 | O42: 18051.82 | P42: 18051.82 | Q42: 18051.82 | R42: 18051.82 | S42: 18051.82 | T42: 18051.82 | U42: =SUM(I42:T42) -> 216621.87
B43: =B42+1 -> 36 | C43: TELEMONT ENGENHARIA E TELECOMUNCAÇOES LTDA | D43: PRIVADO | E43: BOLETO | F43: PORTARIA | G43: MG | H43: =CONCATENATE(F43," ",G43) -> PORTARIA MG | I43: 17581.75 | J43: 17581.75 | K43: 17581.75 | L43: 17581.75 | M43: 17581.75 | N43: 17581.75 | O43: 7618.76 | U43: =SUM(I43:T43) -> 113109.26
...

Sheet COM DADOS BANCARIOS
A1: ESQUADRA TECH - SEGURANCA ELETRONICA & SERVICOS ESPECIALIZADOS LTDA.
A2: DIAF - FATURAMENTO
A3: ANALISE DE CONTRATO X FATURAMENTO
B6: ITEM | C6: CLIENTE | D6: TIPO CONTRATO | E6: FAT - BRUTO JUNHO/18 | F6: FAT - LIQUIDO | G6: FORMA DE PAGAMENTO | H6: LOCAL DE PAGAMENTO | I6: COMPETÊNCIA | J6: EMISSAO | K6: VENCIMENTO
B7: 1 | C7: JHSF - AVEIRO INCORPORACOES LTDA/SHOPPING CIDADE JARDIM | D7: PRIVADO | E7: 15665.76 | F7: 12744.09 | G7: BOLETO | H7: ITAU | I7: MÊS VIGENTE | J7: 1º DIA UTIL | K7: DIA 28
B8: =B7+1 -> 2 | C8: JHSF - CAPRI ADMINISTRADORA DE BENS LTDA | D8: PRIVADO | E8: 3995.39 | F8: 3250.26 | G8: BOLETO | H8: ITAU | I8: MÊS VIGENTE | J8: 1º DIA UTIL | K8: DIA 28
B9: =B8+1 -> 3 | C9: CONDOMINIO EDIFICIO CITTA GIARDINO | D9: PRIVADO | E9: =32012.64 -> 32012.64 | F9: =25081.9 -> 25081.9 | G9: BOLETO | H9: ITAU | I9: MÊS VIGENTE | J9: 1º DIA UTIL | K9: DIA 07
B10: =B9+1 -> 4 | C10: CONDOMINIO MINASCASA O SHOPPING DO LAR | D10: PRIVADO | E10: 36309.07 | F10: 28811.25 | G10: BOLETO | H10: ITAU | I10: MÊS VIGENTE | J10: DIA 18 | K10: DIA 10
B11: =B10+1 -> 5 | C11: CBRE - CONDOMINIO EDIFICIO AURELIANO CHAVES | D11: PRIVADO | E11: 59515 | F11: 47225.15 | G11: BOLETO | H11: ITAU | I11: MÊS ANTERIOR | J11: 1º DIA UTIL | K11: DIA 25
B12: =B11+1 -> 6 | C12: CONDOMINIO EMPRESARIAL SERRA SUL | D12: PRIVADO | E12: 33287.03 | F12: 27411.87 | G12: BOLETO | H12: ITAU | I12: MÊS VIGENTE | J12: 1º DIA UTIL | K12: 45 DIAS APÓS A EMISSÃO
B13: =B12+1 -> 7 | C13: DUFRY LOJAS FRANCAS LTDA | D13: PRIVADO | E13: 6692.38 | F13: 5243.49 | G13: CREDITO EM CONTA | H13: ITAU | I13: MÊS VIGENTE | J13: 1º DIA UTIL | K13: DIA 12 MÊS SUBSEQUENTE
B14: =B13+1 -> 8 | C14: FEDEX BRASIL LOGISTICA E TRANSPORTE LTDA | D14: PRIVADO | E14: 7122.86 | F14: 5794.44 | G14: BOLETO | H14: ITAU | I14: MÊS VIGENTE | J14: DIA 18 | K14: 1º DIA UTIL
B15: =B14+1 -> 9 | C15: GROWN OPTICAL LTDA | D15: PRIVADO | E15: 27489.62 | F15: 22362.81 | G15: CREDITO EM CONTA | H15: ITAU | I15: MÊS ANTERIOR | J15: 1º DIA UTIL | K15: DIA 05
B16: =B15+1 -> 10 | C16: GROWN OPTICAL LTDA - LIMPEZA | D16: PRIVADO | E16: 17810.83 | F16: 14489.11 | G16: CREDITO EM CONTA | H16: ITAU | I16: MÊS ANTERIOR | J16: 1º DIA UTIL | K16: DIA 05
B17: =B16+1 -> 11 | C17: MAGAZINE LUIZA | D17: PRIVADO | E17: 52354.97 | F17: =(6251.86*2)+5948.41+6021.31+6251.86+5741.78 -> 36467.08 | G17: CREDITO EM CONTA | H17: ITAU | I17: MÊS ANTERIOR | J17: 1º DIA UTIL | K17: DIA 20 DO MÊS DA EMISSÃO
B18: =B17+1 -> 12 | C18: MATE COURO S A | D18: PRIVADO | E18: 8394.81 | F18: 6577.33 | G18: BOLETO | H18: ITAU | I18: MÊS VIGENTE | J18: 1º DIA UTIL | K18: 1º DIA UTIL
B19: =B18+1 -> 13 | C19: MINAS TEXTEIS LTDA - AUTONEUM BRASIL | D19: PRIVADO | E19: 21370.83 | F19: 17064.61 | G19: BOLETO | H19: ITAU | I19: MÊS VIGENTE | J19: 1º DIA UTIL | K19: 5º DIA UTIL SUBSEQUENTE
B20: =B19+1 -> 14 | C20: COLIBRI FESTAS - MIX TUDO COMERCIO E SERVIÇOS EIRELLI | D20: PRIVADO | E20: 3817.2 | F20: 2990.78 | G20: BOLETO | H20: ITAU | I20: MÊS VIGENTE | J20: 1º DIA UTIL | K20: 1º DIA UTIL
B21: =B20+1 -> 15 | C21: INDUSTRIA & COMERCIO DE EXPLOSIVOS NITROSUL LTDA - ME | D21: PRIVADO | E21: 14215 | F21: 11492.82 | G21: BOLETO | H21: ITAU | I21: MÊS VIGENTE | J21: 1º DIA UTIL | K21: DIA 05 DO MÊS SUBSEQUENTE
B22: =B21+1 -> 16 | C22: PROCOMP INDUSTRIA ELETRÔNICA | D22: PRIVADO | E22: 14889.15 | F22: 11665.62 | G22: BOLETO | H22: ITAU | I22: MÊS VIGENTE | J22: 1º DIA UTIL | K22: 3º DIA UTIL
B23: =B22+1 -> 17 | C23: PUR EQUIPAMENTOS INDUSTRIAIS KTDA | D23: PRIVADO | E23: 5211.98 | F23: 4187.82 | G23: BOLETO | H23: ITAU | I23: MÊS ANTERIOR | J23: DIA 18 | K23: 1º DIA UTIL
B24: =B23+1 -> 18 | C24: SICOOB NOSSACOOP - Ibirite | D24: PRIVADO | E24: 3713.9 | F24: 3021.25 | G24: BOLETO | H24: ITAU | I24: MÊS VIGENTE | J24: 1º DIA UTIL | K24: 1º DIA UTIL
B25: =B24+1 -> 19 | C25: SICOOB NOSSACOOP - Olegario Maciel | D25: PRIVADO | E25: 3713.9 | F25: 2909.83 | G25: BOLETO | H25: ITAU | I25: MÊS VIGENTE | J25: 1º DIA UTIL | K25: 1º DIA UTIL
B26: =B25+1 -> 20 | C26: SICOOB NOSSACOOP - Mariana | D26: PRIVADO | E26: 3713.9 | F26: 2984.11 | G26: BOLETO | H26: ITAU | I26: MÊS VIGENTE | J26: 1º DIA UTIL | K26: 1º DIA UTIL
B27: =B26+1 -> 21 | C27: SICOOB NOSSACOOP - São José da Lapa | D27: PRIVADO | E27: 3713.9 | F27: 3021.25 | G27: BOLETO | H27: ITAU | I27: MÊS VIGENTE | J27: 1º DIA UTIL | K27: 1º DIA UTIL
B28: =B27+1 -> 22 | C28: SPE INOVA BH S/A | D28: PRIVADO | E28: 18051.82 | F28: 14143.6 | G28: BOLETO | H28: ITAU | I28: MÊS ANTERIOR | J28: DIA 18 | K28: 5º DIA UTIL SUBSEQUENTE
B29: =B28+1 -> 23 | C29: TNT MERCURIO CARGAS E ENCOMENDAS EXPRESSAS S/A | D29: PRIVADO | E29: 15977.6 | F29: 12759.1 | G29: CREDITO EM CONTA | H29: ITAU | I29: MÊS ANTERIOR | J29: 1º DIA UTIL | K29: 60 DIAS APÓS A EMISSAO
... B32: =B31+1 -> 26 | C32: TV GLOBO COMUNICAÇÃO E PARTICIPAÇÃOES S/A | D32: PRIVADO | E32: 194850.79 | F32: 158511.11 | G32: CREDITO EM CONTA | H32: ITAU | I32: MÊS VIGENTE | J32: DIA 21 | K32: DIA 05 DO MÊS SUBSEQUENTE
B33: =B32+1 -> 27 | C33: VIA VAREJO S/A | D33: PRIVADO | E33: 38974.63 | F33: =13298.7+17567.95 -> 30866.65 | G33: CREDITO EM CONTA | H33: ITAU | I33: MÊS VIGENTE | J33: 1º DIA UTIL | K33: 30 DIAS APÓS A EMISSAO
E34: =SUM(E7:E33) -> 908203.12 | F34: =SUM(F7:F33) -> 726929.92

Sheet Plan1
E8: EMISSAO | F8: CLIENTE | G8: COMPETENCIA | H8: SERVIÇO | I8: VR
E9: 43118 | F9: AVEIRO INCORPORACOES LTDA | G9: 43101 | H9: 01.01.004 | I9: 15665.76
E10: 43140 | F10: AVEIRO INCORPORACOES LTDA | G10: 43132 | H10: 01.01.004 | I10: 15665.76
E11: 43171 | F11: AVEIRO INCORPORACOES LTDA | G11: 43160 | H11: 01.01.004 | I11: 15665.76
E12: 43171 | F12: CAPRI ADMINISTRADORA DE BENS LTDA | G12: 43160 | H12: 01.01.004 | I12: 3995.39
E13: 43118 | F13: CAPRI ADMINISTRADORA DE BENS LTDA | G13: 43101 | H13: 01.01.004 | I13: 3995.39
E14: 43140 | F14: CAPRI ADMINISTRADORA DE BENS LTDA | G14: 43132 | H14: 01.01.004 | I14: 3995.39
E15: 43102 | F15: CONDOMINIO EDIFICIO AURELIANO CHAVES | G15: 43101 | H15: 01.01.004 | I15: 59319.43
E16: 43132 | F16: CONDOMINIO EDIFICIO AURELIANO CHAVES | G16: 43101 | H16: 01.01.004 | I16: 59319.43
E17: 43160 | F17: CONDOMINIO EDIFICIO AURELIANO CHAVES | G17: 43132 | H17: 01.01.004 | I17: 59319.43
E18: 43160 | F18: CONDOMINIO EDIFICIO CITTA GIARDINO | G18: 43160 | H18: 01.01.004 | I18: 31080.24
E19: 43102 | F19: CONDOMINIO EDIFICIO CITTA GIARDINO | G19: 43101 | H19: 01.01.004 | I19: 31080.24
E20: 43132 | F20: CONDOMINIO EDIFICIO CITTA GIARDINO | G20: 43132 | H20: 01.01.004 | I20: 31080.24
... E155: 43139 | F155: VIA VAREJO S/A | G155: 43132 | H155: 01.01.004 | I155: 16559.46

Sheet Plan2
E6: Soma de VR | F6: Rótulos de Coluna
E7: Rótulos de Linha | F7: 43040 | G7: 43070 | H7: 43101 | I7: 43132 | J7: 43160 | K7: Total geral
E8: AVEIRO INCORPORACOES LTDA | H8: 15665.76 | I8: 15665.76 | J8: 15665.76 | K8: 46997.28
E9: CAPRI ADMINISTRADORA DE BENS LTDA | H9: 3995.39 | I9: 3995.39 | J9: 3995.39 | K9: 11986.17
E10: CONDOMINIO EDIFICIO AURELIANO CHAVES | H10: 118638.86 | I10: 59319.43 | K10: 177958.29
E11: CONDOMINIO EDIFICIO CITTA GIARDINO | H11: 31080.24 | I11: 31080.24 | J11: 31080.24 | K11: 93240.72
E12: CONDOMINIO EMPRESARIAL SERRA SUL | H12: 40193.39 | I12: 40193.39 | J12: 40193.39 | K12: 120580.17
E13: CONDOMINIO MINASCASA O SHOPPING DO LAR | H13: 34714.22 | I13: 34714.22 | J13: 34714.22 | K13: 104142.66
E14: FEDEX BRASIL LOGISTICA E TRANSPORTE LTDA | H14: 7122.86 | I14: 7122.86 | J14: 7122.86 | K14: 21368.58
E15: FUNDACAO FIAT SAUDE E BEM ESTAR | H15: 6296.62 | K15: 6296.62
E16: GROWN OPTICAL LTDA | H16: 45300.46 | I16: 45300.46 | J16: 45300.46 | K16: 135901.38
E17: INDUSTRIA & COMERCIO DE EXPLOSIVOS NITROSUL LTDA - ME | H17: 14796.27 | I17: 14215 | J17: 14215 | K17: 43226.27
E18: LUFT TRANSPORTES RODOVIARIOS E ARMAZENS GERAIS LTDA | H18: 14547.64 | I18: 14547.64 | J18: 484.92 | K18: 29580.2
E19: MAGAZINE LUIZA S/A | G19: 10089.33 | H19: 169835.32 | I19: 50897.8 | K19: 230822.45
E20: MATE COURO S A | H20: 8032.97 | I20: 8032.97 | J20: 8032.97 | K20: 24098.91
E21: MINAS TEXTEIS - FABRICACAO DE PECAS E PARTES AUTOMOTIVAS LTDA | G21: 20748.38 | I21: 41496.76 | J21: 20748.38 | K21: 82993.52
E22: PROCOMP INDUSTRIA ELETRÔNICA | G22: 14889.15 | I22: 14889.15 | J22: 14889.15 | K22: 44667.45
E23: PUR - EQUIPAMENTOS INDUSTRIAIS KTDA | H23: 5060.18 | I23: 5060.18 | J23: 5060.18 | K23: 15180.54
E24: SPE INOVA BH S/A | H24: 17526.05 | I24: 17526.05 | J24: 17526.05 | K24: 52578.15
E25: TELEMONT ENGENHARIA E TELECOMUNCAÇOES LTDA | H25: 17581.75 | I25: 17581.75 | J25: 17581.75 | K25: 52745.25
E26: TNT MERCURIO CARGAS E ENCOMENDAS EXPRESSAS S/A | H26: 54802.4 | I26: 27401.2 | K26: 82203.6
E27: VIA VAREJO S/A | H27: 61844.22 | I27: 61844.22 | J27: 61844.22 | K27: 185532.66
E28: DUFRY LOJAS FRANCAS LTDA | F28: 439.47 | H28: 13100.69 | I28: 12880.95 | J28: 12880.95 | K28: 39302.06
E29: FL BRASIL HOLDING, LOGISTICA E TRANSPORTE LTDA. | G29: 11009.52 | H29: 237539.41 | I29: 3019.39 | J29: 3019.39 | K29: 254587.71
E30: GLOBO COMUNICACAO E PARTICIPACOES S/A | J30: 686193.05 | K30: 686193.05
E31: MINAS ARENA - GESTAO DE INSTALACOES ESPORTIVAS S.A. | H31: 15080.15 | I31: 34473.83 | J31: 25144.86 | K31: 74698.84
E32: MIX TUDO COMERCIO E SERVICOS EIRELI - ME | H32: 5089.6 | I32: 3817.2 | J32: 3817.2 | K32: 12724
E33: Total geral | F33: 439.47 | G33: 56736.38 | H33: 937844.45 | I33: 565075.84 | J33: 1069510.4 | K33: 2629606.5

Sheet Plan5
H4: EMISSAO | I4: FILIAL | J4: CLIENTE | K4: VR B | L4: VR L | M4: SERVIÇO | N4: CENTRO DE CUSTO
H5: 43455 | I5: 1 | J5: APERAM INOX AMERICA DO SUL S.A | K5: 91843.27 | L5: 73796.07 | M5: Portaria | N5: ARCELOR MITTAL INOX DO BRASIL S/A
H6: 43455 | I6: 1 | J6: APERAM INOX AMERICA DO SUL S.A | K6: 3661.88 | L6: 2942.31 | M6: Portaria | N6: ARCELOR MITTAL INOX DO BRASIL S/A
H7: 43444 | I7: 1 | J7: CAPRI ADMINISTRADORA DE BENS LTDA | K7: 3995.39 | L7: 3250.26 | M7: Portaria | N7: CAPRI ADMINISTRADORA DE BENS LTDA - JHSF
H8: 43447 | I8: 1 | J8: CONDOMINIO DO CENTRO COMERCIAL PORTAL NOVA LIMA | K8: 8773.41 | L8: 7137.17 | M8: Portaria | N8: PRIMORDIAL - Nova Lima
H9: 43447 | I9: 1 | J9: CONDOMINIO DO CENTRO COMERCIAL PORTAL NOVA LIMA | K9: 7833.84 | L9: 6372.82 | M9: Portaria | N9: PRIMORDIAL - Nova Lima
H10: 43440 | I10: 1 | J10: CONDOMINIO EDIFICIO AURELIANO CHAVES | K10: 59410.82 | L10: 47142.49 | M10: Portaria | N10: CONDOMINIO EDIFICIO AURELIANO CHAVES
H11: 43437 | I11: 1 | J11: CONDOMINIO EDIFICIO CITTA GIARDINO - Portaria | K11: 32012.64 | L11: 25402.03 | M11: Portaria | N11: CONDOMINIO EDIFICIO CITTA GIARDINO - Portaria
H12: 43440 | I12: 1 | J12: CONDOMÍNIO EMPRESARIAL SERRA SUL | K12: 47301.53 | L12: 38952.8 | M12: Portaria | N12: CONDOMÍNIO EMPRESARIAL SERRA SUL
H13: 43447 | I13: 1 | J13: CONDOMINIO MINASCASA O SHOPPING DO LAR - MG - Ipiranga - MG | K13: 36309.07 | L13: 28811.25 | M13: Portaria | N13: CONDOMINIO MINASCASA O SHOPPING DO LAR - MG - Ipiranga - MG
H14: 43437 | I14: 1 | J14: DUFRY FREE - Aeroporto Guarulhos | K14: 3346.19 | L14: 2621.74 | M14: Portaria | N14: DUFRY FREE - Aeroporto Guarulhos
H15: 43455 | I15: 1 | J15: GLOBO - BOMBEIRO CIVIL | K15: 251593.23 | L15: 204671.09 | M15: Portaria | N15: GLOBO - BOMBEIRO CIVIL
H16: 43460 | I16: 1 | J16: GLOBOPAR, TV GLOBO, REDE GLOBO E GLOBO.COM | K16: 192809.92 | L16: 156850.87 | M16: Portaria | N16: GLOBO - PORTARIA E RECEPCAO
... H79: 43439 | I79: 1 | J79: VIA VAREJO S/A | K79: 17868.82 | L79: 14268.25 | M79: Portaria | N79: VIA VAREJO - PA 01

Sheet Plan6
D5: Rótulos de Linha | E5: Soma de VR B
D6: APERAM INOX AMERICA DO SUL S.A | E6: 95505.15
D7: CAPRI ADMINISTRADORA DE BENS LTDA | E7: 3995.39
D8: CONDOMINIO DO CENTRO COMERCIAL PORTAL NOVA LIMA | E8: 16607.25
D9: CONDOMINIO EDIFICIO AURELIANO CHAVES | E9: 59410.82
D10: CONDOMINIO EDIFICIO CITTA GIARDINO - Portaria | E10: 32012.64
D11: CONDOMÍNIO EMPRESARIAL SERRA SUL | E11: 47301.53
D12: CONDOMINIO MINASCASA O SHOPPING DO LAR - MG - Ipiranga - MG | E12: 36309.07
D13: DUFRY FREE - Aeroporto Guarulhos | E13: 3346.19
D14: GLOBO - BOMBEIRO CIVIL | E14: 251593.23
D15: GLOBOPAR, TV GLOBO, REDE GLOBO E GLOBO.COM | E15: 192809.92
D16: GPA - GRUPO PAO DE ACUCAR | E16: 187145.7
D17: GROWN OPTICAL LTDA | E17: 51561.87
... D35: Total geral | E35: 2318906.7
