Workbook

Sheet CRA - VERT
A1: 2017
A3: CÉDULA DE CREDITO BANCÁRIO - CTR 200518
A4: CONTRATO | B4: TX. JUROS AA | D4: APROP. JUROS | E4: Custos CTR | F4: ENCARGOS | G4: PERÍODO
A5: 200518 | B5: 0.09120415 | D5: =A9 -> 75527.276 | E5: =A11 -> 34032.209 | F5: =D5+E5 -> 109559.48 | G5: Capitalização | J5: 1197452.3 | K5: Faturado Nufarm
A6: VLR PRODUTOS | B6: TX. JUROS AM | C6: 43008 | D6: =SUM($D$5/$G$15*G6) -> 6814.491 | E6: =SUM($E$5/$G$15*G6) -> 3070.5753 | F6: =SUM(D6:E6) -> 9885.0663 | G6: 24 | J6: 1212936.5 | K6: Liberado CRA
A7: ='Detalhamento VERT'!D23 -> 802973.85 | B7: 0.0073 | C7: 43039 | D7: =SUM($D$5/$G$15*G7) -> 8802.0509 | E7: =SUM($E$5/$G$15*G7) -> 3966.1597 | F7: =SUM(D7:E7) -> 12768.211 | G7: 31 | J7: =J6-J5 -> 15484.17 | K7: Crédito a utilizar
A8: JUROS | B8: TX. JUROS AD | C8: 43069 | D8: =SUM($D$5/$G$15*G8) -> 8518.1138 | E8: =SUM($E$5/$G$15*G8) -> 3838.2191 | F8: =SUM(D8:E8) -> 12356.333 | G8: 30
A9: ='Detalhamento VERT'!D17 -> 75527.276 | B9: =(1+B7)^(1/30)-1 -> 0.00024247886 | C9: 43099 | D9: =SUM($D$5/$G$15*G9) -> 8802.0509 | E9: =SUM($E$5/$G$15*G9) -> 3966.1597 | F9: =SUM(D9:E9) -> 12768.211 | G9: 31 | I9: 42984 | J9: 1180387.5 | K9: Liberação Nufarm
A10: Custos CTR | B10: DATA DESEMB. | C10: 43130 | D10: =SUM($D$5/$G$15*G10) -> 8802.0509 | E10: =SUM($E$5/$G$15*G10) -> 3966.1597 | F10: =SUM(D10:E10) -> 12768.211 | G10: 31 | I10: 42984 | J10: 32548.97 | K10: Liberação Nufarm
A11: ='Detalhamento VERT'!D22 -> 34032.209 | B11: 42984 | C11: 43159 | D11: =SUM($D$5/$G$15*G11) -> 7950.2395 | E11: =SUM($E$5/$G$15*G11) -> 3582.3378 | F11: =SUM(D11:E11) -> 11532.577 | G11: 28 | I11: 14.247 | J11: =J9+J10 -> 1212936.5
A12: VLR CONTRATADO | B12: VENCIMENTO | C12: 43189 | D12: =SUM($D$5/$G$15*G12) -> 8802.0509 | E12: =SUM($E$5/$G$15*G12) -> 3966.1597 | F12: =SUM(D12:E12) -> 12768.211 | G12: 31
A13: =A7+A9+A11 -> 912533.33 | B13: 43250 | C13: 43220 | D13: =SUM($D$5/$G$15*G13) -> 8518.1138 | E13: =SUM($E$5/$G$15*G13) -> 3838.2191 | F13: =SUM(D13:E13) -> 12356.333 | G13: 30
B14: ENCARGOS | C14: 43250 | D14: =SUM($D$5/$G$15*G14) -> 8518.1138 | E14: =SUM($E$5/$G$15*G14) -> 3838.2191 | F14: =SUM(D14:E14) -> 12356.333 | G14: 30 | I14: 13.892 | J14: 785768.54 | K14: Liberação Dow
B15: =A9+A11 -> 109559.48 | C15: Total | D15: =SUM(D6:D14) -> 75527.276 | E15: =SUM(E6:E14) -> 34032.209 | F15: =SUM(F6:F14) -> 109559.48 | G15: =SUM(G6:G14) -> 266
A16: Credito | J16: 1414448.1
A17: 0 | J17: 912533.33
J18: =J16+J17 -> 2326981.5 | K18: =A7/J18 -> 0.34507101
A19: GARANTIA:
A20: JUROS S/ FINANCIAMENTO CRA VERT SECURITIZADORA CTR N° 200518
A26: CÉDULA DE CREDITO BANCÁRIO - CTR 200918
A27: CONTRATO | B27: TX. JUROS AA | D27: APROP. JUROS | E27: Custos CTR | F27: ENCARGOS | G27: PERÍODO
A28: 200918 | B28: 0.09120415 | D28: =A32 -> 165966.09 | E28: =A34 -> 52750.739 | F28: =D28+E28 -> 218716.83 | G28: Capitalização | J28: 1197452.3 | K28: Faturado Nufarm
A29: VLR PRODUTOS | B29: TX. JUROS AM | C29: 43008 | D29: =SUM($D$28/$G$42*G29) -> 10319.135 | E29: =SUM($E$28/$G$42*G29) -> 3279.8387 | F29: =SUM(D29:E29) -> 13598.974 | G29: 24 | J29: 1212936.5 | K29: Liberado CRA
A30: ='Detalhamento VERT'!G23 -> 1195731.3 | B30: 0.0073 | C30: 43039 | D30: =SUM($D$28/$G$42*G30) -> 13328.883 | E30: =SUM($E$28/$G$42*G30) -> 4236.4583 | F30: =SUM(D30:E30) -> 17565.341 | G30: 31 | J30: =J29-J28 -> 15484.17 | K30: Crédito a utilizar
A31: JUROS | B31: TX. JUROS AD | C31: 43069 | D31: =SUM($D$28/$G$42*G31) -> 12898.919 | E31: =SUM($E$28/$G$42*G31) -> 4099.7984 | F31: =SUM(D31:E31) -> 16998.717 | G31: 30
A32: ='Detalhamento VERT'!G17 -> 165966.09 | B32: =(1+B30)^(1/30)-1 -> 0.00024247886 | C32: 43099 | D32: =SUM($D$28/$G$42*G32) -> 13328.883 | E32: =SUM($E$28/$G$42*G32) -> 4236.4583 | F32: =SUM(D32:E32) -> 17565.341 | G32: 31 | I32: 42984 | J32: 1180387.5 | K32: Liberação Nufarm
A33: Custos CTR | B33: DATA DESEMB. | C33: 43130 | D33: =SUM($D$28/$G$42*G33) -> 13328.883 | E33: =SUM($E$28/$G$42*G33) -> 4236.4583 | F33: =SUM(D33:E33) -> 17565.341 | G33: 31 | I33: 42984 | J33: 32548.97 | K33: Liberação Nufarm
A34: ='Detalhamento VERT'!G22 -> 52750.739 | B34: 42984 | C34: 43159 | D34: =SUM($D$28/$G$42*G34) -> 12038.991 | E34: =SUM($E$28/$G$42*G34) -> 3826.4785 | F34: =SUM(D34:E34) -> 15865.469 | G34: 28 | I34: 14.247 | J34: =J32+J33 -> 1212936.5
A35: VLR CONTRATADO | B35: VENCIMENTO | C35: 43189 | D35: =SUM($D$28/$G$42*G35) -> 13328.883 | E35: =SUM($E$28/$G$42*G35) -> 4236.4583 | F35: =SUM(D35:E35) -> 17565.341 | G35: 31
A36: =A30+A32+A34 -> 1414448.1 | B36: 43371 | C36: 43220 | D36: =SUM($D$28/$G$42*G36) -> 12898.919 | E36: =SUM($E$28/$G$42*G36) -> 4099.7984 | F36: =SUM(D36:E36) -> 16998.717 | G36: 30
B37: ENCARGOS | C37: 43250 | D37: =SUM($D$28/$G$42*G37) -> 12898.919 | E37: =SUM($E$28/$G$42*G37) -> 4099.7984 | F37: =SUM(D37:E37) -> 16998.717 | G37: 30 | I37: 13.892 | J37: 785768.54 | K37: Liberação Dow
B38: =A32+A34 -> 218716.83 | C38: 43281 | D38: =SUM($D$28/$G$42*G38) -> 12898.919 | E38: =SUM($E$28/$G$42*G38) -> 4099.7984 | F38: =SUM(D38:E38) -> 16998.717 | G38: 30
C39: 43311 | D39: =SUM($D$28/$G$42*G39) -> 13328.883 | E39: =SUM($E$28/$G$42*G39) -> 4236.4583 | F39: =SUM(D39:E39) -> 17565.341 | G39: 31 | J39: 1414448.1
A40: Credito | C40: 43342 | D40: =SUM($D$28/$G$42*G40) -> 13328.883 | E40: =SUM($E$28/$G$42*G40) -> 4236.4583 | F40: =SUM(D40:E40) -> 17565.341 | G40: 31 | J40: 912533.33
A41: 0 | C41: 43373 | D41: =SUM($D$28/$G$42*G41) -> 12038.991 | E41: =SUM($E$28/$G$42*G41) -> 3826.4785 | F41: =SUM(D41:E41) -> 15865.469 | G41: 28 | J41: =J39+J40 -> 2326981.5 | K41: =A30/J41 -> 0.51385511
C42: Total | D42: =SUM(D29:D41) -> 165966.09 | E42: =SUM(E29:E41) -> 52750.739 | F42: =SUM(F29:F41) -> 218716.83 | G42: =SUM(G29:G41) -> 386
A44: GARANTIA:
A45: JUROS S/ FINANCIAMENTO CRA VERT SECURITIZADORA CTR N° 200918
A47: 2018
A49: CÉDULA DE CREDITO BANCÁRIO - CTR 020519
...

Sheet JUROS
A1: SALDO DE JUROS MENSAL
A4: 43009 | B4: CP | C4: LP | D4: TOTAL
A5: BCO SAFRA | B5: =SUM('CRA - VERT'!D8:D18) -> 135438.01 | C5: 0 | D5: =B5+C5 -> 135438.01
B6: =SUM(B5:B5) -> 135438.01 | C6: =SUM(C5:C5) -> 0 | D6: =SUM(D5:E5) -> 135438.01
A8: 43040 | B8: CP | C8: LP | D8: TOTAL
A9: BCO SAFRA | C9: 0 | D9: =B9+C9 -> 0
B10: =SUM(B9:B9) -> 0 | C10: =SUM(C9:C9) -> 0 | D10: =SUM(D9:E9) -> 0
A12: 43070 | B12: CP | C12: LP | D12: TOTAL
A13: BCO SAFRA | C13: 0 | D13: =B13+C13 -> 0
B14: =SUM(B13:B13) -> 0 | C14: =SUM(C13:C13) -> 0 | D14: =SUM(D13:E13) -> 0

Sheet Detalhamento VERT
F3: CRA NUFARM II - RELATÓRIO DE DESEMBOLSOS
C5: DATA DO RELATÓRIO | D5: 42997
C7: PARTICIPANTE
C8: Razão Social | D8: CULTIVAR - COMERCIO E REPRESENTACOES LTD
C9: CNPJ | D9: 22.055.456/0001-91
C11: CDCA/CPR-F
C12: 43221 | F12: 43344
C13: Data de Desembolso | D13: 42979 | F13: Data de Desembolso | G13: 42979
C14: Data de Vencimento | D14: 43265 | F14: Data de Vencimento | G14: 43388
C15: Prazo (dias úteis) | D15: 193 | F15: Prazo (dias úteis) | G15: 278
C16: VALOR DEVIDO NO VENCIMENTO DO CDCA/CPR | D16: 912533 | F16: VALOR DEVIDO NO VENCIMENTO DO CDCA/CPR | G16: 1414448
C17: JUROS S/ A OPERAÇÃO | D17: =D16-D22-D23+0.33 -> 75527.276 | F17: JUROS S/ A OPERAÇÃO | G17: =G16-G22-G23+0.13 -> 165966.09
C18: Taxa de juros compostos CRA (a.a.) 101% CDI | D18: 0.11941164 | F18: Taxa de juros compostos CRA (a.a.) 101% CDI | G18: 0.11978638
C19: Taxa de juros compostos CRA (a.m.) 101% CDI | D19: =(1+D18)^(1/12)-1 -> 0.00944459 | F19: Taxa de juros compostos CRA (a.m.) 101% CDI | G19: =(1+G18)^(1/12)-1 -> 0.0094727467
C20: VALOR PRESENTE DO CDCA/CPR | D20: =D16/((1+D18)^(D15/252)) -> 837006.05 | F20: VALOR PRESENTE DO CDCA/CPR | G20: =G16/((1+G18)^(G15/252)) -> 1248482
C22: Custos cobrados | D22: =IF(G16=0,$D$42*$G$38,$D$42*$G$38*$G$40) -> 34032.209 | F22: Custos cobrados | G22: =IF(D16=0,$D$42*$G$38,$D$42*$G$38*$G$41) -> 52750.739
C23: PREÇO DE AQUISIÇÃO DE INSUMOS | D23: =D20-D22 -> 802973.85 | F23: PREÇO DE AQUISIÇÃO DE INSUMOS | G23: =G20-G22 -> 1195731.3
C24: TAXA (a.a.) incluindo custos e juros dos investidores | D24: =(D16/D23)^(252/D15)-1 -> 0.18175629 | F24: TAXA (a.a.) incluindo custos e juros dos investidores | G24: =(G16/G23)^(252/G15)-1 -> 0.16447564
C25: TAXA (a.m.) incluindo custos e juros dos investidores | D25: =(1+D24)^(1/12)-1 -> 0.014014099 | F25: TAXA (a.m.) incluindo custos e juros dos investidores | G25: =(1+G24)^(1/12)-1 -> 0.012770091
C26: Taxa no período incluindo custos e juros investidores | D26: =(D16/D23)-100% -> 0.13644175 | F26: Taxa no período incluindo custos e juros investidores | G26: =(G16/G23)-100% -> 0.18291458
C28: PAGAMENTOS DE FORNECEDORES
C29: NUFARM | F29: OUTROS FORNECEDORES
C30: Valor Utilizado | D30: =1180387.52+32548.97 -> 1212936.5 | F30: Valor Utilizado | G30: 785768.66
D31: Saldo Disponível | E31: =(D23+G23)-(D30+G30) -> 0
C33: CUSTOS
C35: DETALHAMENTO DOS CUSTOS TOTAIS DA EMISSÃO DE CRA | F35: PARTICIPAÇÃO DE SUA EMISSÃO NOS CUSTOS TOTAIS
C36: Comissões | D36: 1248483.5 | E36: =D36*$G$38 -> 32841.135 | F36: Valor Total da Emissão de CRA vendido | G36: 79281594
C37: Seguro de Crédito | D37: 1111496.4 | E37: =D37*$G$38 -> 29237.714 | F37: Valor total presenta de sua emissão | G37: =D20+G20 -> 2085488.1
C38: Hedge (Opção DI) | D38: 260303.03 | E38: =D38*$G$38 -> 6847.2244 | F38: % SUA PARTICIPAÇÃO NOS CUSTOS | G38: =G37/G36 -> 0.02630482
C39: Advogados | D39: 592852.76 | E39: =D39*$G$38 -> 15594.885
C40: Outros Prestadores de Serviço | D40: 85991.454 | E40: =D40*$G$38 -> 2261.9897 | F40: % CRA com Vcto. em Maio/18 | G40: =D16/(D16+G16) -> 0.39215318
F41: % CRA com Vcto. em Setembro/18 | G41: =1-G40 -> 0.60784682
C42: TOTAL | D42: =SUM(D36:D41) -> 3299127.2 | E42: =D42*$G$38 -> 86782.948
G43: =G37-'CRA - VERT'!A7 -> 1282514.3

Sheet Conversão de Taxas
B1: Taxa que você tem | C1: Taxa que você quer | E1: N | F1: I | G1: PV | H1: PMT | I1: FV | J1: JUROS
A2: Mês para ano: (1+Taxa)^12-1 | B2: 0.01530947 | C2: =(1+B2)^12-1 -> 0.19999999 | E2: 173 | F2: =C4 -> 0.00044333316 | G2: 404405.19 | I2: =G2+J2 -> 435421.71 | J2: =SUM((G2*F2)*E2) -> 31016.518
A3: Ano para mês: (1+Taxa)^(1/12)-1 | B3: 0.2 | C3: =(1+B3)^(1/12)-1 -> 0.01530947
A4: Ano para dia: (1+Taxa)^(1/360)-1 | B4: 0.173 | C4: =(1+B4)^(1/360)-1 -> 0.00044333316
A6: Dia para mês: (1+Taxa)^30-1 | B6: 0.05 | C6: =(1+B6)^30-1 -> 3.3219424
A7: Dia para ano: (1+Taxa)^360-1 | B7: 0.0003756825 | C7: =(1+B7)^360-1 -> 0.14478896
A8: Mês para dia: (1+Taxa)^(1/30)-1 | B8: 0.01530947 | C8: =(1+B8)^(1/30)-1 -> 0.00050657702
A9: Mês para ano: (1+Taxa)^12-1
A10: Ano para dia: (1+Taxa)^(1/360)-1
A11: Ano para mês: (1+Taxa)^(1/12)-1

Sheet Saldo IMPLANTAÇÃO
B1: CRA - Vert Securitizadora | F1: CRA - Vert Securitizadora
B2: 1966156.2 | C2: 0 | D2: =B2+C2 -> 1966156.2 | F2: 1966156.2 | G2: 0 | H2: =F2+G2 -> 1966156.2 | I2: =B2-F2 -> 0 | J2: =C2-G2 -> 0 | K2: =I2+J2 -> 0

Sheet Relac. Notas Fiscais
G1: Cliente: | H1: 20808-6 - CULTIVAR - COMERCIO E REPRESENTACOES LTDA
G2: Fone: | H2: 67 3454-3287/67 3454-5623
G3: FAX:
G4: Moeda | H4: R$ | I4: US$
G5: Taxa: | H5: 0 | I5: 0 | J5: %
G6: Pontual: | H6: 0 | I6: 0 | J6: %
G7: Desc Fin: | H7: 0 | I7: 0 | J7: %
G8: Tar Bcia: | H8: 0 | I8: 0 | J8: %
G9: Cotação Dia: | H9: 0
G10: Cotação Utl: | H10: 0
G11: Deságio Ptax | H11: 0
G12: Dt.Base: | H12: 42997
F13: Valor Adiantado: | H13: 0
A14: Est | B14: Esp | C14: Ser | D14: Título | E14: PA | F14: Portador | G14: Emissão | H14: Vencto | I14: Vl Original | J14: Saldo Pnd | K14: Vl Mov R$ | L14: VL Mov R$ DIA | M14: Dias | N14: Moe Ped | O14: Cot Fat | P14: Tot Moeda | Q14: Tot Moeda Mov | R14: Cot Dia | S14: Vl Líquido II | T14: OBS | U14: Produto | V14: Qtde Total | W14: Vl Unit | X14: Vl Total NF | Y14: Pedido | Z14: Nat. DP | AA14: Cliente | AB14: Dt Impl Ped | AC14: Carteira
A15: 11 | B15: DP | C15: 1 | D15: 0087079 | E15: 2 | F15: CRA CLIENTE | G15: 42944 | H15: 42965 | I15: 142500 | J15: 142500 | K15: 142500 | L15: 142500 | M15: -32 | N15: REAL | O15: 1 | P15: 142500 | Q15: 142500 | R15: 1 | S15: 142500 | T15: LIQUIDAR | U15: U46 PRIME - 20L | V15: 15000 | W15: 9.5 | X15: 142500 | Y15: 300038649 | Z15: DN | AA15: 20808 | AB15: 42905 | AC15: CAR
A16: 11 | B16: DP | C16: 1 | D16: 0087079 | E16: 1 | F16: CRA CLIENTE | G16: 42944 | H16: 42965 | I16: 210330 | J16: 210330 | K16: 210330 | L16: 210330 | M16: -32 | N16: REAL | O16: 1 | P16: 210330 | Q16: 210330 | R16: 1 | S16: 210330 | T16: LIQUIDAR | U16: CRUCIAL - 20L | V16: 17100 | W16: 12.3 | X16: 210330 | Y16: 300038649 | Z16: DN | AA16: 20808 | AB16: 42905 | AC16: CAR
A17: 11 | B17: DP | C17: 1 | D17: 0087746 | E17: 1 | F17: CRA CLIENTE | G17: 42965 | H17: 42965 | I17: 4800 | J17: 4800 | K17: 4800 | L17: 4800 | M17: -32 | N17: REAL | O17: 1 | P17: 4800 | Q17: 4800 | R17: 1 | S17: 4800 | T17: LIQUIDAR | U17: NUPRID 700 WG (10X1) KG | V17: 60 | W17: 80 | X17: 4800 | Y17: 300038649 | Z17: DN | AA17: 20808 | AB17: 42905 | AC17: CAR
A18: 11 | B18: DP | C18: 1 | D18: 0087748 | E18: 1 | F18: CRA CLIENTE | G18: 42965 | H18: 42965 | I18: 35670 | J18: 35670 | K18: 35670 | L18: 35670 | M18: -32 | N18: REAL | O18: 1 | P18: 35670 | Q18: 35670 | R18: 1 | S18: 35670 | T18: LIQUIDAR | U18: CRUCIAL - 20L | V18: 2900 | W18: 12.3 | X18: 35670 | Y18: 300038649 | Z18: DN | AA18: 20808 | AB18: 42905 | AC18: CAR
A19: 13 | B19: DP | C19: 1 | D19: 0016110 | E19: 4 | F19: CRA CLIENTE | G19: 42935 | H19: 42965 | I19: 45500 | J19: 45500 | K19: 45500 | L19: 45500 | M19: -32 | N19: REAL | O19: 1 | P19: 45500 | Q19: 45500 | R19: 1 | S19: 45500 | T19: LIQUIDAR | U19: PLATINUM NEO (4X5)L | V19: 500 | W19: 91 | X19: 45500 | Y19: 300038649 | Z19: DN | AA19: 20808 | AB19: 42905 | AC19: CAR
A20: 13 | B20: DP | C20: 1 | D20: 0016111 | E20: 1 | F20: CRA CLIENTE | G20: 42935 | H20: 42965 | I20: 38000 | J20: 38000 | K20: 38000 | L20: 38000 | M20: -32 | N20: REAL | O20: 1 | P20: 38000 | Q20: 38000 | R20: 1 | S20: 38000 | T20: LIQUIDAR | U20: ZETHAPYR 106 SL - 20 L (BALDE) | V20: 2000 | W20: 19 | X20: 38000 | Y20: 300038649 | Z20: DN | AA20: 20808 | AB20: 42905 | AC20: CAR
A21: 13 | B21: DP | C21: 1 | D21: 0016115 | E21: 1 | F21: CRA CLIENTE | G21: 42935 | H21: 42965 | I21: 37000 | J21: 37000 | K21: 37000 | L21: 37000 | M21: -32 | N21: REAL | O21: 1 | P21: 37000 | Q21: 37000 | R21: 1 | S21: 37000 | T21: LIQUIDAR | U21: ABAMEX (4X5)L | V21: 2000 | W21: 18.5 | X21: 37000 | Y21: 300038649 | Z21: DN | AA21: 20808 | AB21: 42905 | AC21: CAR
A22: 13 | B22: DP | C22: 1 | D22: 0016110 | E22: 1 | F22: CRA CLIENTE | G22: 42935 | H22: 42965 | I22: 33778.32 | J22: 33778.32 | K22: 33778.32 | L22: 33778.32 | M22: -32 | N22: REAL | O22: 1 | P22: 33778.32 | Q22: 33778.32 | R22: 1 | S22: 33778.32 | T22: LIQUIDAR | U22: DIMAX 480 SC (12X1L) | V22: 408 | W22: 82.79 | X22: 33778.32 | Y22: 300038649 | Z22: DN | AA22: 20808 | AB22: 42905 | AC22: CAR
A23: 13 | B23: DP | C23: 1 | D23: 0016110 | E23: 3 | F23: CRA CLIENTE | G23: 42935 | H23: 42965 | I23: 20000 | J23: 20000 | K23: 20000 | L23: 20000 | M23: -32 | N23: REAL | O23: 1 | P23: 20000 | Q23: 20000 | R23: 1 | S23: 20000 | T23: LIQUIDAR | U23: KROMO 250 WG - 20X500G | V23: 500 | W23: 40 | X23: 20000 | Y23: 300038649 | Z23: DN | AA23: 20808 | AB23: 42905 | AC23: CAR
A24: 13 | B24: DP | C24: 1 | D24: 0016110 | E24: 2 | F24: CRA CLIENTE | G24: 42935 | H24: 42965 | I24: 100800 | J24: 100800 | K24: 100800 | L24: 100800 | M24: -32 | N24: REAL | O24: 1 | P24: 100800 | Q24: 100800 | R24: 1 | S24: 100800 | T24: LIQUIDAR | U24: NUPRID 700 WG (10X1) KG | V24: 1260 | W24: 80 | X24: 100800 | Y24: 300038649 | Z24: DN | AA24: 20808 | AB24: 42905 | AC24: CAR
A25: 11 | B25: DP | C25: 1 | D25: 0087970 | E25: 1 | F25: CRA CLIENTE | G25: 42972 | H25: 42972 | I25: 54400 | J25: 54400 | K25: 54400 | L25: 54400 | M25: -25 | N25: REAL | O25: 1 | P25: 54400 | Q25: 54400 | R25: 1 | S25: 54400 | T25: LIQUIDAR | U25: NUPRID 700 WG (10X1) KG | V25: 680 | W25: 80 | X25: 54400 | Y25: 300038649 | Z25: DN | AA25: 20808 | AB25: 42905 | AC25: CAR
A26: 11 | B26: DP | C26: 1 | D26: 0086920 | E26: 1 | F26: CRA CLIENTE | G26: 42942 | H26: 42965 | I26: 142500 | J26: 142500 | K26: 142500 | L26: 142500 | M26: -32 | N26: REAL | O26: 1 | P26: 142500 | Q26: 142500 | R26: 1 | S26: 142500 | T26: LIQUIDAR | U26: U46 PRIME - 20L | V26: 15000 | W26: 9.5 | X26: 142500 | Y26: 300038660 | Z26: DN | AA26: 21933 | AB26: 42905 | AC26: CAR
... A34: 13 | B34: DP | C34: 1 | D34: 0016090 | E34: 1 | F34: CRA CLIENTE | G34: 42935 | H34: 42965 | I34: 61500 | J34: 61500 | K34: 61500 | L34: 61500 | M34: -32 | N34: REAL | O34: 1 | P34: 61500 | Q34: 61500 | R34: 1 | S34: 61500 | T34: LIQUIDAR | U34: CRUCIAL - 20L | V34: 5000 | W34: 12.3 | X34: 61500 | Y34: 300038663 | Z34: DN | AA34: 22731 | AB34: 42905 | AC34: CAR
I35: 1197452.3 | J35: 1197452.3 | K35: 1197452.3 | L35: 1197452.3 | P35: 1197452.3 | Q35: 1197452.3 | S35: 1197452.3 | V35: TOTAL PEDIDOS | X35: =SUM(X15:X34) -> 1197452.3
V36: CRA CLIENTE VERT | X36: 1212936.5
X37: =X36-X35 -> 15484.17 | Y37: A CREDITO DO CLIENTE
